Workbook
Name ApprovalStatus: '参数字典'!$O$2:$O$6
Name CollabType: '参数字典'!$N$2:$N$5
Name EvidenceStatus: '参数字典'!$S$2:$S$5
Name LeadStatus: '参数字典'!$M$2:$M$13
Name ReviewStatus: '参数字典'!$Q$2:$Q$7
Name SampleStatus: '参数字典'!$P$2:$P$9
Name YesNo: '参数字典'!$R$2:$R$3

Sheet 参数字典
A1: 分类 | B1: 资料项 | C1: 当前已核实值（未知留空） | D1: 单位 / 适用口径 | E1: 证据或资料位置 | F1: 核对负责人 | G1: 核对日期 | H1: 有效 / 到期日期 | I1: 状态 | J1: 下次核对日期 | K1: 备注 / 待确认问题 | M1: LeadStatus | N1: CollabType | O1: ApprovalStatus | P1: SampleStatus | Q1: ReviewStatus | R1: YesNo | S1: EvidenceStatus
A2: 商品 | B2: SKU 与商品全名 | D2: 区分规格、口味、组合、版本，防止错链 | I2: 待核实 | M2: 待筛选 | N2: 纯佣 | O2: 待申请 | P2: 待审批 | Q2: 待发布 | R2: 是 | S2: 待核实
A3: 商品 | B3: 规格 / 净含量 / 件数 | D3: 与实物包装、商品详情页一致 | I3: 待核实 | M3: 待触达 | N3: 固定费+佣金 | O3: 审批中 | P3: 待发出 | Q3: 已发布观察 | R3: 否 | S3: 已确认
A4: 商品 | B4: 配料表 | D4: 用当前版本包装或审核资料；不凭口感推断 | I4: 待核实 | M4: 已触达 | N4: 固定费 | O4: 已批准 | P4: 运输中 | Q4: 待结算 | S4: 已过期
A5: 商品 | B5: 过敏原与交叉接触说明 | D5: 以包装及已审核资料为准，不自行推断 | I5: 待核实 | M5: 沟通中 | N5: 其他待核实 | O5: 已拒绝 | P5: 已签收 | Q5: 已复盘 | S5: 不适用
A6: 商品 | B6: 营养标签 | D6: 按包装标注单位、每份/每100克，避免混用 | I6: 待核实 | M6: 待审批 | O6: 不涉及 | P6: 待反馈 | Q6: 异常
A7: 商品 | B7: 生产 / 经营资质与许可 | D7: 核实主体、商品与经营范围，资料仅限授权用途 | I7: 待核实 | M7: 待寄样 | P7: 已完成 | Q7: 终止
A8: 商品 | B8: 生产批次 / 保质期 | D8: 记录适用批次与起算条件，不能以旧批次代替 | I8: 待核实 | M8: 试用中 | P8: 异常
A9: 商品 | B9: 储存方式与食用方法 | D9: 与包装要求一致；常温/冷藏等不自行假定 | I9: 待核实 | M9: 待发布 | P9: 已取消
A10: 商品 | B10: 卖点证据与禁用宣称 | D10: 口味等主观感受标明；功效、绝对化、产地等须有证据 | I10: 待核实 | M10: 已发布观察
A11: 价格 | B11: 日常价 / 活动价 / 券后价 | D11: 区分商家承担与平台承担优惠及生效区间 | I11: 待核实 | M11: 待结算
A12: 价格 | B12: 达人专属机制与变更权限 | D12: 谁可批价、批佣、批固定费，超限交谁批准 | I12: 待核实 | M12: 复盘完成
A13: 利润 | B13: 单笔售后后净收入口径 | D13: 尚未扣本模型费用；勿把已扣佣结算净额再次扣佣 | I13: 待核实 | M13: 终止
A14: 利润 | B14: 有效计佣销售额与佣金规则 | D14: 以合同及后台为准，核对退款、补贴、税费和阶梯规则 | I14: 待核实
A15: 利润 | B15: 平台 / 支付费计提基数 | D15: 费率、基数、退款返还等以实际约定为准 | I15: 待核实
A16: 利润 | B16: 货品 / 包材 / 履约 / 售后损失 | D16: 完整退款订单的不可回收费用需计入，不重复扣损失 | I16: 待核实
A17: 履约 | B17: 发货地 / 发货时效 | D17: 核对承诺、截单时间、预售和节假日例外 | I17: 待核实
A18: 履约 | B18: 可售库存与查询频率 | D18: 可售库存、活动库存、预留量分别确认 | I18: 待核实
A19: 履约 | B19: 配送与包邮地区 | D19: 偏远地区、运费、无法配送范围 | I19: 待核实
A20: 履约 | B20: 售后口径与升级负责人 | D20: 破损、漏发、质量异议、退款责任及举证流程 | I20: 待核实
A21: 预算 | B21: 固定费 / 寄样预算与审批链 | D21: 审批额度、财务付款要求、收款主体核验 | I21: 待核实
A22: 结算 | B22: 订单归因窗口 | D22: 区分视频、直播、店铺自然、投流，重叠窗口不能直接相加 | I22: 待核实
A23: 结算 | B23: 数据截至与最终结算周期 | D23: 支付数据、售后后数据与平台结算数据分开 | I23: 待核实
A24: 结算 | B24: 固定费 / 寄样费用分摊规则 | D24: 一合作多视频时只分摊一次，总额必须对得上 | I24: 待核实
A25: 协作 | B25: 商务 / 内容 / 客服 / 供应链联系人 | D25: 谁负责，谁审批，异常向谁升级 | I25: 待核实
... A28: 目标 | B28: 部门 KPI 与考核口径 | D28: 待公司确认；不预设触达量、视频量或 GMV 指标 | I28: 待核实

Sheet 达人线索与合作
A1: 线索ID | B1: 合作ID | C1: 达人UID | D1: 达人名称 | E1: 主页链接 | F1: 负责人 | G1: 线索来源 | H1: 内容类目 / 场景 | I1: 人群场景匹配1–5 | J1: 相关视频播放中位数 | K1: 观察样本起日 | L1: 观察样本止日 | M1: 样本条数 | N1: 类目成交证据位置 | O1: 退款 / 履约观察 | P1: 异常 / 历史合作记录 | Q1: 合作形式 | R1: 固定费报价 | S1: 佣金比例 | T1: 当前状态 | U1: 首次录入日期 | V1: 最近跟进日期 | W1: 下次跟进日期 | X1: 约定发片日期 | Y1: 拟合作SKU / 版本 | Z1: 预算审批状态 | AA1: 审批凭据位置 | AB1: 沟通结论 / 退出原因 | AC1: 首次触达日期 | AD1: 达成合作日期 | AE1: 商品资料确认日期 | AF1: 记录检查（自动）
AF2: =IF(A2="","",IF(COUNTIF($A$2:$A$301,A2)>1,"线索ID重复",IF(AND(B2<>"",COUNTIF($B$2:$B$301,B2)>1),"合作ID重复：一合作一行",IF(OR(F2="",T2="",U2=""),"待补负责人/状态/录入日","已建档；继续核对证据"))))
AF3: =IF(A3="","",IF(COUNTIF($A$2:$A$301,A3)>1,"线索ID重复",IF(AND(B3<>"",COUNTIF($B$2:$B$301,B3)>1),"合作ID重复：一合作一行",IF(OR(F3="",T3="",U3=""),"待补负责人/状态/录入日","已建档；继续核对证据"))))
AF4: =IF(A4="","",IF(COUNTIF($A$2:$A$301,A4)>1,"线索ID重复",IF(AND(B4<>"",COUNTIF($B$2:$B$301,B4)>1),"合作ID重复：一合作一行",IF(OR(F4="",T4="",U4=""),"待补负责人/状态/录入日","已建档；继续核对证据"))))
AF5: =IF(A5="","",IF(COUNTIF($A$2:$A$301,A5)>1,"线索ID重复",IF(AND(B5<>"",COUNTIF($B$2:$B$301,B5)>1),"合作ID重复：一合作一行",IF(OR(F5="",T5="",U5=""),"待补负责人/状态/录入日","已建档；继续核对证据"))))
AF6: =IF(A6="","",IF(COUNTIF($A$2:$A$301,A6)>1,"线索ID重复",IF(AND(B6<>"",COUNTIF($B$2:$B$301,B6)>1),"合作ID重复：一合作一行",IF(OR(F6="",T6="",U6=""),"待补负责人/状态/录入日","已建档；继续核对证据"))))
AF7: =IF(A7="","",IF(COUNTIF($A$2:$A$301,A7)>1,"线索ID重复",IF(AND(B7<>"",COUNTIF($B$2:$B$301,B7)>1),"合作ID重复：一合作一行",IF(OR(F7="",T7="",U7=""),"待补负责人/状态/录入日","已建档；继续核对证据"))))
AF8: =IF(A8="","",IF(COUNTIF($A$2:$A$301,A8)>1,"线索ID重复",IF(AND(B8<>"",COUNTIF($B$2:$B$301,B8)>1),"合作ID重复：一合作一行",IF(OR(F8="",T8="",U8=""),"待补负责人/状态/录入日","已建档；继续核对证据"))))
AF9: =IF(A9="","",IF(COUNTIF($A$2:$A$301,A9)>1,"线索ID重复",IF(AND(B9<>"",COUNTIF($B$2:$B$301,B9)>1),"合作ID重复：一合作一行",IF(OR(F9="",T9="",U9=""),"待补负责人/状态/录入日","已建档；继续核对证据"))))
AF10: =IF(A10="","",IF(COUNTIF($A$2:$A$301,A10)>1,"线索ID重复",IF(AND(B10<>"",COUNTIF($B$2:$B$301,B10)>1),"合作ID重复：一合作一行",IF(OR(F10="",T10="",U10=""),"待补负责人/状态/录入日","已建档；继续核对证据"))))
AF11: =IF(A11="","",IF(COUNTIF($A$2:$A$301,A11)>1,"线索ID重复",IF(AND(B11<>"",COUNTIF($B$2:$B$301,B11)>1),"合作ID重复：一合作一行",IF(OR(F11="",T11="",U11=""),"待补负责人/状态/录入日","已建档；继续核对证据"))))
AF12: =IF(A12="","",IF(COUNTIF($A$2:$A$301,A12)>1,"线索ID重复",IF(AND(B12<>"",COUNTIF($B$2:$B$301,B12)>1),"合作ID重复：一合作一行",IF(OR(F12="",T12="",U12=""),"待补负责人/状态/录入日","已建档；继续核对证据"))))
AF13: =IF(A13="","",IF(COUNTIF($A$2:$A$301,A13)>1,"线索ID重复",IF(AND(B13<>"",COUNTIF($B$2:$B$301,B13)>1),"合作ID重复：一合作一行",IF(OR(F13="",T13="",U13=""),"待补负责人/状态/录入日","已建档；继续核对证据"))))
... AF301: =IF(A301="","",IF(COUNTIF($A$2:$A$301,A301)>1,"线索ID重复",IF(AND(B301<>"",COUNTIF($B$2:$B$301,B301)>1),"合作ID重复：一合作一行",IF(OR(F301="",T301="",U301=""),"待补负责人/状态/录入日","已建档；继续核对证据"))))

Sheet 寄样履约
A1: 寄样单ID | B1: 合作ID | C1: 达人UID | D1: 负责人 | E1: SKU / 口味 / 批次 | F1: 申请日期 | G1: 批准日期 | H1: 寄出日期 | I1: 快递公司 | J1: 运单号 | K1: 签收日期 | L1: 约定反馈日期 | M1: 试用反馈 | N1: 约定发片日期 | O1: 样品货品成本 | P1: 样品包材 | Q1: 寄样物流费 | R1: 寄样总投入（自动） | S1: 当前状态 | T1: 下次跟进日期 | U1: 异常问题 / 升级人 | V1: 审批凭据位置 | W1: 收件信息受限存储位置 | X1: 签收凭证位置 | Y1: 商品资料已确认 | Z1: 记录检查（自动）
R2: =IF(A2="","",IF(COUNT(O2:Q2)<3,"待补充",IF(MIN(O2:Q2)<0,"检查输入",SUM(O2:Q2)))) | Z2: =IF(A2="","",IF(COUNTIF($A$2:$A$301,A2)>1,"寄样单ID重复",IF(OR(B2="",D2="",S2=""),"待补合作/负责人/状态",IF(COUNTIF('达人线索与合作'!$B$2:$B$301,B2)<>1,"合作ID未唯一匹配","已关联；核对审批与签收"))))
R3: =IF(A3="","",IF(COUNT(O3:Q3)<3,"待补充",IF(MIN(O3:Q3)<0,"检查输入",SUM(O3:Q3)))) | Z3: =IF(A3="","",IF(COUNTIF($A$2:$A$301,A3)>1,"寄样单ID重复",IF(OR(B3="",D3="",S3=""),"待补合作/负责人/状态",IF(COUNTIF('达人线索与合作'!$B$2:$B$301,B3)<>1,"合作ID未唯一匹配","已关联；核对审批与签收"))))
R4: =IF(A4="","",IF(COUNT(O4:Q4)<3,"待补充",IF(MIN(O4:Q4)<0,"检查输入",SUM(O4:Q4)))) | Z4: =IF(A4="","",IF(COUNTIF($A$2:$A$301,A4)>1,"寄样单ID重复",IF(OR(B4="",D4="",S4=""),"待补合作/负责人/状态",IF(COUNTIF('达人线索与合作'!$B$2:$B$301,B4)<>1,"合作ID未唯一匹配","已关联；核对审批与签收"))))
R5: =IF(A5="","",IF(COUNT(O5:Q5)<3,"待补充",IF(MIN(O5:Q5)<0,"检查输入",SUM(O5:Q5)))) | Z5: =IF(A5="","",IF(COUNTIF($A$2:$A$301,A5)>1,"寄样单ID重复",IF(OR(B5="",D5="",S5=""),"待补合作/负责人/状态",IF(COUNTIF('达人线索与合作'!$B$2:$B$301,B5)<>1,"合作ID未唯一匹配","已关联；核对审批与签收"))))
R6: =IF(A6="","",IF(COUNT(O6:Q6)<3,"待补充",IF(MIN(O6:Q6)<0,"检查输入",SUM(O6:Q6)))) | Z6: =IF(A6="","",IF(COUNTIF($A$2:$A$301,A6)>1,"寄样单ID重复",IF(OR(B6="",D6="",S6=""),"待补合作/负责人/状态",IF(COUNTIF('达人线索与合作'!$B$2:$B$301,B6)<>1,"合作ID未唯一匹配","已关联；核对审批与签收"))))
R7: =IF(A7="","",IF(COUNT(O7:Q7)<3,"待补充",IF(MIN(O7:Q7)<0,"检查输入",SUM(O7:Q7)))) | Z7: =IF(A7="","",IF(COUNTIF($A$2:$A$301,A7)>1,"寄样单ID重复",IF(OR(B7="",D7="",S7=""),"待补合作/负责人/状态",IF(COUNTIF('达人线索与合作'!$B$2:$B$301,B7)<>1,"合作ID未唯一匹配","已关联；核对审批与签收"))))
R8: =IF(A8="","",IF(COUNT(O8:Q8)<3,"待补充",IF(MIN(O8:Q8)<0,"检查输入",SUM(O8:Q8)))) | Z8: =IF(A8="","",IF(COUNTIF($A$2:$A$301,A8)>1,"寄样单ID重复",IF(OR(B8="",D8="",S8=""),"待补合作/负责人/状态",IF(COUNTIF('达人线索与合作'!$B$2:$B$301,B8)<>1,"合作ID未唯一匹配","已关联；核对审批与签收"))))
R9: =IF(A9="","",IF(COUNT(O9:Q9)<3,"待补充",IF(MIN(O9:Q9)<0,"检查输入",SUM(O9:Q9)))) | Z9: =IF(A9="","",IF(COUNTIF($A$2:$A$301,A9)>1,"寄样单ID重复",IF(OR(B9="",D9="",S9=""),"待补合作/负责人/状态",IF(COUNTIF('达人线索与合作'!$B$2:$B$301,B9)<>1,"合作ID未唯一匹配","已关联；核对审批与签收"))))
R10: =IF(A10="","",IF(COUNT(O10:Q10)<3,"待补充",IF(MIN(O10:Q10)<0,"检查输入",SUM(O10:Q10)))) | Z10: =IF(A10="","",IF(COUNTIF($A$2:$A$301,A10)>1,"寄样单ID重复",IF(OR(B10="",D10="",S10=""),"待补合作/负责人/状态",IF(COUNTIF('达人线索与合作'!$B$2:$B$301,B10)<>1,"合作ID未唯一匹配","已关联；核对审批与签收"))))
R11: =IF(A11="","",IF(COUNT(O11:Q11)<3,"待补充",IF(MIN(O11:Q11)<0,"检查输入",SUM(O11:Q11)))) | Z11: =IF(A11="","",IF(COUNTIF($A$2:$A$301,A11)>1,"寄样单ID重复",IF(OR(B11="",D11="",S11=""),"待补合作/负责人/状态",IF(COUNTIF('达人线索与合作'!$B$2:$B$301,B11)<>1,"合作ID未唯一匹配","已关联；核对审批与签收"))))
R12: =IF(A12="","",IF(COUNT(O12:Q12)<3,"待补充",IF(MIN(O12:Q12)<0,"检查输入",SUM(O12:Q12)))) | Z12: =IF(A12="","",IF(COUNTIF($A$2:$A$301,A12)>1,"寄样单ID重复",IF(OR(B12="",D12="",S12=""),"待补合作/负责人/状态",IF(COUNTIF('达人线索与合作'!$B$2:$B$301,B12)<>1,"合作ID未唯一匹配","已关联；核对审批与签收"))))
R13: =IF(A13="","",IF(COUNT(O13:Q13)<3,"待补充",IF(MIN(O13:Q13)<0,"检查输入",SUM(O13:Q13)))) | Z13: =IF(A13="","",IF(COUNTIF($A$2:$A$301,A13)>1,"寄样单ID重复",IF(OR(B13="",D13="",S13=""),"待补合作/负责人/状态",IF(COUNTIF('达人线索与合作'!$B$2:$B$301,B13)<>1,"合作ID未唯一匹配","已关联；核对审批与签收"))))
... R301: =IF(A301="","",IF(COUNT(O301:Q301)<3,"待补充",IF(MIN(O301:Q301)<0,"检查输入",SUM(O301:Q301)))) | Z301: =IF(A301="","",IF(COUNTIF($A$2:$A$301,A301)>1,"寄样单ID重复",IF(OR(B301="",D301="",S301=""),"待补合作/负责人/状态",IF(COUNTIF('达人线索与合作'!$B$2:$B$301,B301)<>1,"合作ID未唯一匹配","已关联；核对审批与签收"))))

Sheet 视频与订单复盘
A1: 归因记录ID | B1: 合作ID | C1: 视频ID | D1: SKU / 版本 | E1: 归因窗口起 | F1: 归因窗口止 | G1: 数据截至日期 | H1: 负责人 | I1: 发布日期 | J1: 视频链接 | K1: 播放量 | L1: 商品点击量 | M1: 支付订单 | N1: 支付GMV | O1: 退款金额 | P1: 有效净收入（未扣本表费用） | Q1: 有效计佣销售额 | R1: 实际佣金 | S1: 平台 / 支付费 | T1: 有效结算订单 | U1: 货品+包材+履约实际成本 | V1: 其他变动成本 | W1: 固定费分摊 | X1: 样品与物流分摊 | Y1: 贡献估算（自动） | Z1: 归因口径证据位置 | AA1: 复盘结论 / 下轮动作 | AB1: 下次复盘日期 | AC1: 当前状态 | AD1: 是否纳入汇总 | AE1: 分摊口径说明 | AF1: 记录检查（自动） | AG1: 视频唯一计数（自动）
Y2: =IF(A2="","",IF(COUNT(P2,R2:S2,U2:X2)<7,"待补充",IF(MIN(P2,R2:S2,U2:X2)<0,"检查输入",ROUND(P2-SUM(R2:S2)-SUM(U2:X2),4)))) | AF2: =IF(A2="","",IF(COUNTIF($A$2:$A$301,A2)>1,"归因记录ID重复",IF(OR(B2="",C2="",D2="",H2="",COUNT(E2:G2)<3,I2="",Z2=""),"待补归因/证据/日期",IF(F2<E2,"窗口起止错误",IF(COUNTIF('达人线索与合作'!$B$2:$B$301,B2)<>1,"合作ID未唯一匹配",IF(COUNTIFS($B$2:$B$301,B2,$C$2:$C$301,C2,$D$2:$D$301,D2,$E$2:$E$301,E2,$F$2:$F$301,F2)>1,"窗口重复：应更新原行",IF(AND(AD2="是",COUNTIFS($B$2:$B$301,B2,$C$2:$C$301,C2,$D$2:$D$301,D2,$AD$2:$AD$301,"是")>1),"重复汇总：同视频SKU仅选一行",IF(AND(AC2="已复盘",AD2="是",ISNUMBER(Y2),AE2<>""),"可汇总","观察中/未完成结算核对")))))))) | AG2: =IF(C2="","",IF(OR(H2="",I2=""),"待补充",IF(COUNTIFS($C$2:$C$301,C2,$H$2:$H$301,H2,$I$2:$I$301,I2)<>COUNTIF($C$2:$C$301,C2),"请统一日期/负责人",IF(COUNTIF($C$2:C2,C2)=1,1,0))))
Y3: =IF(A3="","",IF(COUNT(P3,R3:S3,U3:X3)<7,"待补充",IF(MIN(P3,R3:S3,U3:X3)<0,"检查输入",ROUND(P3-SUM(R3:S3)-SUM(U3:X3),4)))) | AF3: =IF(A3="","",IF(COUNTIF($A$2:$A$301,A3)>1,"归因记录ID重复",IF(OR(B3="",C3="",D3="",H3="",COUNT(E3:G3)<3,I3="",Z3=""),"待补归因/证据/日期",IF(F3<E3,"窗口起止错误",IF(COUNTIF('达人线索与合作'!$B$2:$B$301,B3)<>1,"合作ID未唯一匹配",IF(COUNTIFS($B$2:$B$301,B3,$C$2:$C$301,C3,$D$2:$D$301,D3,$E$2:$E$301,E3,$F$2:$F$301,F3)>1,"窗口重复：应更新原行",IF(AND(AD3="是",COUNTIFS($B$2:$B$301,B3,$C$2:$C$301,C3,$D$2:$D$301,D3,$AD$2:$AD$301,"是")>1),"重复汇总：同视频SKU仅选一行",IF(AND(AC3="已复盘",AD3="是",ISNUMBER(Y3),AE3<>""),"可汇总","观察中/未完成结算核对")))))))) | AG3: =IF(C3="","",IF(OR(H3="",I3=""),"待补充",IF(COUNTIFS($C$2:$C$301,C3,$H$2:$H$301,H3,$I$2:$I$301,I3)<>COUNTIF($C$2:$C$301,C3),"请统一日期/负责人",IF(COUNTIF($C$2:C3,C3)=1,1,0))))
Y4: =IF(A4="","",IF(COUNT(P4,R4:S4,U4:X4)<7,"待补充",IF(MIN(P4,R4:S4,U4:X4)<0,"检查输入",ROUND(P4-SUM(R4:S4)-SUM(U4:X4),4)))) | AF4: =IF(A4="","",IF(COUNTIF($A$2:$A$301,A4)>1,"归因记录ID重复",IF(OR(B4="",C4="",D4="",H4="",COUNT(E4:G4)<3,I4="",Z4=""),"待补归因/证据/日期",IF(F4<E4,"窗口起止错误",IF(COUNTIF('达人线索与合作'!$B$2:$B$301,B4)<>1,"合作ID未唯一匹配",IF(COUNTIFS($B$2:$B$301,B4,$C$2:$C$301,C4,$D$2:$D$301,D4,$E$2:$E$301,E4,$F$2:$F$301,F4)>1,"窗口重复：应更新原行",IF(AND(AD4="是",COUNTIFS($B$2:$B$301,B4,$C$2:$C$301,C4,$D$2:$D$301,D4,$AD$2:$AD$301,"是")>1),"重复汇总：同视频SKU仅选一行",IF(AND(AC4="已复盘",AD4="是",ISNUMBER(Y4),AE4<>""),"可汇总","观察中/未完成结算核对")))))))) | AG4: =IF(C4="","",IF(OR(H4="",I4=""),"待补充",IF(COUNTIFS($C$2:$C$301,C4,$H$2:$H$301,H4,$I$2:$I$301,I4)<>COUNTIF($C$2:$C$301,C4),"请统一日期/负责人",IF(COUNTIF($C$2:C4,C4)=1,1,0))))
Y5: =IF(A5="","",IF(COUNT(P5,R5:S5,U5:X5)<7,"待补充",IF(MIN(P5,R5:S5,U5:X5)<0,"检查输入",ROUND(P5-SUM(R5:S5)-SUM(U5:X5),4)))) | AF5: =IF(A5="","",IF(COUNTIF($A$2:$A$301,A5)>1,"归因记录ID重复",IF(OR(B5="",C5="",D5="",H5="",COUNT(E5:G5)<3,I5="",Z5=""),"待补归因/证据/日期",IF(F5<E5,"窗口起止错误",IF(COUNTIF('达人线索与合作'!$B$2:$B$301,B5)<>1,"合作ID未唯一匹配",IF(COUNTIFS($B$2:$B$301,B5,$C$2:$C$301,C5,$D$2:$D$301,D5,$E$2:$E$301,E5,$F$2:$F$301,F5)>1,"窗口重复：应更新原行",IF(AND(AD5="是",COUNTIFS($B$2:$B$301,B5,$C$2:$C$301,C5,$D$2:$D$301,D5,$AD$2:$AD$301,"是")>1),"重复汇总：同视频SKU仅选一行",IF(AND(AC5="已复盘",AD5="是",ISNUMBER(Y5),AE5<>""),"可汇总","观察中/未完成结算核对")))))))) | AG5: =IF(C5="","",IF(OR(H5="",I5=""),"待补充",IF(COUNTIFS($C$2:$C$301,C5,$H$2:$H$301,H5,$I$2:$I$301,I5)<>COUNTIF($C$2:$C$301,C5),"请统一日期/负责人",IF(COUNTIF($C$2:C5,C5)=1,1,0))))
Y6: =IF(A6="","",IF(COUNT(P6,R6:S6,U6:X6)<7,"待补充",IF(MIN(P6,R6:S6,U6:X6)<0,"检查输入",ROUND(P6-SUM(R6:S6)-SUM(U6:X6),4)))) | AF6: =IF(A6="","",IF(COUNTIF($A$2:$A$301,A6)>1,"归因记录ID重复",IF(OR(B6="",C6="",D6="",H6="",COUNT(E6:G6)<3,I6="",Z6=""),"待补归因/证据/日期",IF(F6<E6,"窗口起止错误",IF(COUNTIF('达人线索与合作'!$B$2:$B$301,B6)<>1,"合作ID未唯一匹配",IF(COUNTIFS($B$2:$B$301,B6,$C$2:$C$301,C6,$D$2:$D$301,D6,$E$2:$E$301,E6,$F$2:$F$301,F6)>1,"窗口重复：应更新原行",IF(AND(AD6="是",COUNTIFS($B$2:$B$301,B6,$C$2:$C$301,C6,$D$2:$D$301,D6,$AD$2:$AD$301,"是")>1),"重复汇总：同视频SKU仅选一行",IF(AND(AC6="已复盘",AD6="是",ISNUMBER(Y6),AE6<>""),"可汇总","观察中/未完成结算核对")))))))) | AG6: =IF(C6="","",IF(OR(H6="",I6=""),"待补充",IF(COUNTIFS($C$2:$C$301,C6,$H$2:$H$301,H6,$I$2:$I$301,I6)<>COUNTIF($C$2:$C$301,C6),"请统一日期/负责人",IF(COUNTIF($C$2:C6,C6)=1,1,0))))
Y7: =IF(A7="","",IF(COUNT(P7,R7:S7,U7:X7)<7,"待补充",IF(MIN(P7,R7:S7,U7:X7)<0,"检查输入",ROUND(P7-SUM(R7:S7)-SUM(U7:X7),4)))) | AF7: =IF(A7="","",IF(COUNTIF($A$2:$A$301,A7)>1,"归因记录ID重复",IF(OR(B7="",C7="",D7="",H7="",COUNT(E7:G7)<3,I7="",Z7=""),"待补归因/证据/日期",IF(F7<E7,"窗口起止错误",IF(COUNTIF('达人线索与合作'!$B$2:$B$301,B7)<>1,"合作ID未唯一匹配",IF(COUNTIFS($B$2:$B$301,B7,$C$2:$C$301,C7,$D$2:$D$301,D7,$E$2:$E$301,E7,$F$2:$F$301,F7)>1,"窗口重复：应更新原行",IF(AND(AD7="是",COUNTIFS($B$2:$B$301,B7,$C$2:$C$301,C7,$D$2:$D$301,D7,$AD$2:$AD$301,"是")>1),"重复汇总：同视频SKU仅选一行",IF(AND(AC7="已复盘",AD7="是",ISNUMBER(Y7),AE7<>""),"可汇总","观察中/未完成结算核对")))))))) | AG7: =IF(C7="","",IF(OR(H7="",I7=""),"待补充",IF(COUNTIFS($C$2:$C$301,C7,$H$2:$H$301,H7,$I$2:$I$301,I7)<>COUNTIF($C$2:$C$301,C7),"请统一日期/负责人",IF(COUNTIF($C$2:C7,C7)=1,1,0))))
Y8: =IF(A8="","",IF(COUNT(P8,R8:S8,U8:X8)<7,"待补充",IF(MIN(P8,R8:S8,U8:X8)<0,"检查输入",ROUND(P8-SUM(R8:S8)-SUM(U8:X8),4)))) | AF8: =IF(A8="","",IF(COUNTIF($A$2:$A$301,A8)>1,"归因记录ID重复",IF(OR(B8="",C8="",D8="",H8="",COUNT(E8:G8)<3,I8="",Z8=""),"待补归因/证据/日期",IF(F8<E8,"窗口起止错误",IF(COUNTIF('达人线索与合作'!$B$2:$B$301,B8)<>1,"合作ID未唯一匹配",IF(COUNTIFS($B$2:$B$301,B8,$C$2:$C$301,C8,$D$2:$D$301,D8,$E$2:$E$301,E8,$F$2:$F$301,F8)>1,"窗口重复：应更新原行",IF(AND(AD8="是",COUNTIFS($B$2:$B$301,B8,$C$2:$C$301,C8,$D$2:$D$301,D8,$AD$2:$AD$301,"是")>1),"重复汇总：同视频SKU仅选一行",IF(AND(AC8="已复盘",AD8="是",ISNUMBER(Y8),AE8<>""),"可汇总","观察中/未完成结算核对")))))))) | AG8: =IF(C8="","",IF(OR(H8="",I8=""),"待补充",IF(COUNTIFS($C$2:$C$301,C8,$H$2:$H$301,H8,$I$2:$I$301,I8)<>COUNTIF($C$2:$C$301,C8),"请统一日期/负责人",IF(COUNTIF($C$2:C8,C8)=1,1,0))))
Y9: =IF(A9="","",IF(COUNT(P9,R9:S9,U9:X9)<7,"待补充",IF(MIN(P9,R9:S9,U9:X9)<0,"检查输入",ROUND(P9-SUM(R9:S9)-SUM(U9:X9),4)))) | AF9: =IF(A9="","",IF(COUNTIF($A$2:$A$301,A9)>1,"归因记录ID重复",IF(OR(B9="",C9="",D9="",H9="",COUNT(E9:G9)<3,I9="",Z9=""),"待补归因/证据/日期",IF(F9<E9,"窗口起止错误",IF(COUNTIF('达人线索与合作'!$B$2:$B$301,B9)<>1,"合作ID未唯一匹配",IF(COUNTIFS($B$2:$B$301,B9,$C$2:$C$301,C9,$D$2:$D$301,D9,$E$2:$E$301,E9,$F$2:$F$301,F9)>1,"窗口重复：应更新原行",IF(AND(AD9="是",COUNTIFS($B$2:$B$301,B9,$C$2:$C$301,C9,$D$2:$D$301,D9,$AD$2:$AD$301,"是")>1),"重复汇总：同视频SKU仅选一行",IF(AND(AC9="已复盘",AD9="是",ISNUMBER(Y9),AE9<>""),"可汇总","观察中/未完成结算核对")))))))) | AG9: =IF(C9="","",IF(OR(H9="",I9=""),"待补充",IF(COUNTIFS($C$2:$C$301,C9,$H$2:$H$301,H9,$I$2:$I$301,I9)<>COUNTIF($C$2:$C$301,C9),"请统一日期/负责人",IF(COUNTIF($C$2:C9,C9)=1,1,0))))
Y10: =IF(A10="","",IF(COUNT(P10,R10:S10,U10:X10)<7,"待补充",IF(MIN(P10,R10:S10,U10:X10)<0,"检查输入",ROUND(P10-SUM(R10:S10)-SUM(U10:X10),4)))) | AF10: =IF(A10="","",IF(COUNTIF($A$2:$A$301,A10)>1,"归因记录ID重复",IF(OR(B10="",C10="",D10="",H10="",COUNT(E10:G10)<3,I10="",Z10=""),"待补归因/证据/日期",IF(F10<E10,"窗口起止错误",IF(COUNTIF('达人线索与合作'!$B$2:$B$301,B10)<>1,"合作ID未唯一匹配",IF(COUNTIFS($B$2:$B$301,B10,$C$2:$C$301,C10,$D$2:$D$301,D10,$E$2:$E$301,E10,$F$2:$F$301,F10)>1,"窗口重复：应更新原行",IF(AND(AD10="是",COUNTIFS($B$2:$B$301,B10,$C$2:$C$301,C10,$D$2:$D$301,D10,$AD$2:$AD$301,"是")>1),"重复汇总：同视频SKU仅选一行",IF(AND(AC10="已复盘",AD10="是",ISNUMBER(Y10),AE10<>""),"可汇总","观察中/未完成结算核对")))))))) | AG10: =IF(C10="","",IF(OR(H10="",I10=""),"待补充",IF(COUNTIFS($C$2:$C$301,C10,$H$2:$H$301,H10,$I$2:$I$301,I10)<>COUNTIF($C$2:$C$301,C10),"请统一日期/负责人",IF(COUNTIF($C$2:C10,C10)=1,1,0))))
Y11: =IF(A11="","",IF(COUNT(P11,R11:S11,U11:X11)<7,"待补充",IF(MIN(P11,R11:S11,U11:X11)<0,"检查输入",ROUND(P11-SUM(R11:S11)-SUM(U11:X11),4)))) | AF11: =IF(A11="","",IF(COUNTIF($A$2:$A$301,A11)>1,"归因记录ID重复",IF(OR(B11="",C11="",D11="",H11="",COUNT(E11:G11)<3,I11="",Z11=""),"待补归因/证据/日期",IF(F11<E11,"窗口起止错误",IF(COUNTIF('达人线索与合作'!$B$2:$B$301,B11)<>1,"合作ID未唯一匹配",IF(COUNTIFS($B$2:$B$301,B11,$C$2:$C$301,C11,$D$2:$D$301,D11,$E$2:$E$301,E11,$F$2:$F$301,F11)>1,"窗口重复：应更新原行",IF(AND(AD11="是",COUNTIFS($B$2:$B$301,B11,$C$2:$C$301,C11,$D$2:$D$301,D11,$AD$2:$AD$301,"是")>1),"重复汇总：同视频SKU仅选一行",IF(AND(AC11="已复盘",AD11="是",ISNUMBER(Y11),AE11<>""),"可汇总","观察中/未完成结算核对")))))))) | AG11: =IF(C11="","",IF(OR(H11="",I11=""),"待补充",IF(COUNTIFS($C$2:$C$301,C11,$H$2:$H$301,H11,$I$2:$I$301,I11)<>COUNTIF($C$2:$C$301,C11),"请统一日期/负责人",IF(COUNTIF($C$2:C11,C11)=1,1,0))))
Y12: =IF(A12="","",IF(COUNT(P12,R12:S12,U12:X12)<7,"待补充",IF(MIN(P12,R12:S12,U12:X12)<0,"检查输入",ROUND(P12-SUM(R12:S12)-SUM(U12:X12),4)))) | AF12: =IF(A12="","",IF(COUNTIF($A$2:$A$301,A12)>1,"归因记录ID重复",IF(OR(B12="",C12="",D12="",H12="",COUNT(E12:G12)<3,I12="",Z12=""),"待补归因/证据/日期",IF(F12<E12,"窗口起止错误",IF(COUNTIF('达人线索与合作'!$B$2:$B$301,B12)<>1,"合作ID未唯一匹配",IF(COUNTIFS($B$2:$B$301,B12,$C$2:$C$301,C12,$D$2:$D$301,D12,$E$2:$E$301,E12,$F$2:$F$301,F12)>1,"窗口重复：应更新原行",IF(AND(AD12="是",COUNTIFS($B$2:$B$301,B12,$C$2:$C$301,C12,$D$2:$D$301,D12,$AD$2:$AD$301,"是")>1),"重复汇总：同视频SKU仅选一行",IF(AND(AC12="已复盘",AD12="是",ISNUMBER(Y12),AE12<>""),"可汇总","观察中/未完成结算核对")))))))) | AG12: =IF(C12="","",IF(OR(H12="",I12=""),"待补充",IF(COUNTIFS($C$2:$C$301,C12,$H$2:$H$301,H12,$I$2:$I$301,I12)<>COUNTIF($C$2:$C$301,C12),"请统一日期/负责人",IF(COUNTIF($C$2:C12,C12)=1,1,0))))
Y13: =IF(A13="","",IF(COUNT(P13,R13:S13,U13:X13)<7,"待补充",IF(MIN(P13,R13:S13,U13:X13)<0,"检查输入",ROUND(P13-SUM(R13:S13)-SUM(U13:X13),4)))) | AF13: =IF(A13="","",IF(COUNTIF($A$2:$A$301,A13)>1,"归因记录ID重复",IF(OR(B13="",C13="",D13="",H13="",COUNT(E13:G13)<3,I13="",Z13=""),"待补归因/证据/日期",IF(F13<E13,"窗口起止错误",IF(COUNTIF('达人线索与合作'!$B$2:$B$301,B13)<>1,"合作ID未唯一匹配",IF(COUNTIFS($B$2:$B$301,B13,$C$2:$C$301,C13,$D$2:$D$301,D13,$E$2:$E$301,E13,$F$2:$F$301,F13)>1,"窗口重复：应更新原行",IF(AND(AD13="是",COUNTIFS($B$2:$B$301,B13,$C$2:$C$301,C13,$D$2:$D$301,D13,$AD$2:$AD$301,"是")>1),"重复汇总：同视频SKU仅选一行",IF(AND(AC13="已复盘",AD13="是",ISNUMBER(Y13),AE13<>""),"可汇总","观察中/未完成结算核对")))))))) | AG13: =IF(C13="","",IF(OR(H13="",I13=""),"待补充",IF(COUNTIFS($C$2:$C$301,C13,$H$2:$H$301,H13,$I$2:$I$301,I13)<>COUNTIF($C$2:$C$301,C13),"请统一日期/负责人",IF(COUNTIF($C$2:C13,C13)=1,1,0))))
... Y301: =IF(A301="","",IF(COUNT(P301,R301:S301,U301:X301)<7,"待补充",IF(MIN(P301,R301:S301,U301:X301)<0,"检查输入",ROUND(P301-SUM(R301:S301)-SUM(U301:X301),4)))) | AF301: =IF(A301="","",IF(COUNTIF($A$2:$A$301,A301)>1,"归因记录ID重复",IF(OR(B301="",C301="",D301="",H301="",COUNT(E301:G301)<3,I301="",Z301=""),"待补归因/证据/日期",IF(F301<E301,"窗口起止错误",IF(COUNTIF('达人线索与合作'!$B$2:$B$301,B301)<>1,"合作ID未唯一匹配",IF(COUNTIFS($B$2:$B$301,B301,$C$2:$C$301,C301,$D$2:$D$301,D301,$E$2:$E$301,E301,$F$2:$F$301,F301)>1,"窗口重复：应更新原行",IF(AND(AD301="是",COUNTIFS($B$2:$B$301,B301,$C$2:$C$301,C301,$D$2:$D$301,D301,$AD$2:$AD$301,"是")>1),"重复汇总：同视频SKU仅选一行",IF(AND(AC301="已复盘",AD301="是",ISNUMBER(Y301),AE301<>""),"可汇总","观察中/未完成结算核对")))))))) | AG301: =IF(C301="","",IF(OR(H301="",I301=""),"待补充",IF(COUNTIFS($C$2:$C$301,C301,$H$2:$H$301,H301,$I$2:$I$301,I301)<>COUNTIF($C$2:$C$301,C301),"请统一日期/负责人",IF(COUNTIF($C$2:C301,C301)=1,1,0))))

Sheet 报价测算
A1: 测算ID | B1: 合作ID | C1: SKU / 版本 | D1: 场景与有效订单口径 | E1: 证据 / 参数版本位置 | F1: 单笔售后后净收入 | G1: 单笔有效计佣销售额 | H1: 单笔货品成本 | I1: 单笔包材 | J1: 单笔履约运费 | K1: 单笔其他变动成本 | L1: 佣金比例 | M1: 平台 / 支付费率 | N1: 单笔平台费计费基数 | O1: 固定合作费 | P1: 样品+包材+寄样物流总投入 | Q1: 情景有效订单数（可选） | R1: 单笔佣金（自动） | S1: 单笔平台费（自动） | T1: 单笔贡献（自动） | U1: 前置总投入（自动） | V1: 保本有效订单数（自动） | W1: 情景贡献（自动） | X1: 预算审批状态 | Y1: 负责人 | Z1: 测算日期 | AA1: 下次校准日期 | AB1: 风险备注 / 待核实项
R2: =IF(A2="","",IF(COUNT(G2,L2)<2,"待补充",IF(OR(G2<0,L2<0,L2>1),"检查输入",G2*L2))) | S2: =IF(A2="","",IF(COUNT(M2:N2)<2,"待补充",IF(OR(M2<0,M2>1,N2<0),"检查输入",M2*N2))) | T2: =IF(A2="","",IF(COUNT(F2:N2)<9,"待补充",IF(OR(MIN(F2:N2)<0,L2>1,M2>1),"检查输入",ROUND(F2-SUM(H2:K2)-R2-S2,4)))) | U2: =IF(A2="","",IF(COUNT(O2:P2)<2,"待补充",IF(MIN(O2:P2)<0,"检查输入",SUM(O2:P2)))) | V2: =IF(A2="","",IF(OR(T2="检查输入",U2="检查输入"),"检查输入",IF(OR(NOT(ISNUMBER(T2)),NOT(ISNUMBER(U2))),"待补充",IF(T2<=0,"不可保本",IFERROR(ROUNDUP(U2/T2,0),"检查输入"))))) | W2: =IF(A2="","",IF(OR(NOT(ISNUMBER(T2)),NOT(ISNUMBER(U2)),NOT(ISNUMBER(Q2))),"待补充",IF(OR(Q2<0,Q2<>INT(Q2)),"检查输入",ROUND(Q2*T2-U2,4))))
R3: =IF(A3="","",IF(COUNT(G3,L3)<2,"待补充",IF(OR(G3<0,L3<0,L3>1),"检查输入",G3*L3))) | S3: =IF(A3="","",IF(COUNT(M3:N3)<2,"待补充",IF(OR(M3<0,M3>1,N3<0),"检查输入",M3*N3))) | T3: =IF(A3="","",IF(COUNT(F3:N3)<9,"待补充",IF(OR(MIN(F3:N3)<0,L3>1,M3>1),"检查输入",ROUND(F3-SUM(H3:K3)-R3-S3,4)))) | U3: =IF(A3="","",IF(COUNT(O3:P3)<2,"待补充",IF(MIN(O3:P3)<0,"检查输入",SUM(O3:P3)))) | V3: =IF(A3="","",IF(OR(T3="检查输入",U3="检查输入"),"检查输入",IF(OR(NOT(ISNUMBER(T3)),NOT(ISNUMBER(U3))),"待补充",IF(T3<=0,"不可保本",IFERROR(ROUNDUP(U3/T3,0),"检查输入"))))) | W3: =IF(A3="","",IF(OR(NOT(ISNUMBER(T3)),NOT(ISNUMBER(U3)),NOT(ISNUMBER(Q3))),"待补充",IF(OR(Q3<0,Q3<>INT(Q3)),"检查输入",ROUND(Q3*T3-U3,4))))
R4: =IF(A4="","",IF(COUNT(G4,L4)<2,"待补充",IF(OR(G4<0,L4<0,L4>1),"检查输入",G4*L4))) | S4: =IF(A4="","",IF(COUNT(M4:N4)<2,"待补充",IF(OR(M4<0,M4>1,N4<0),"检查输入",M4*N4))) | T4: =IF(A4="","",IF(COUNT(F4:N4)<9,"待补充",IF(OR(MIN(F4:N4)<0,L4>1,M4>1),"检查输入",ROUND(F4-SUM(H4:K4)-R4-S4,4)))) | U4: =IF(A4="","",IF(COUNT(O4:P4)<2,"待补充",IF(MIN(O4:P4)<0,"检查输入",SUM(O4:P4)))) | V4: =IF(A4="","",IF(OR(T4="检查输入",U4="检查输入"),"检查输入",IF(OR(NOT(ISNUMBER(T4)),NOT(ISNUMBER(U4))),"待补充",IF(T4<=0,"不可保本",IFERROR(ROUNDUP(U4/T4,0),"检查输入"))))) | W4: =IF(A4="","",IF(OR(NOT(ISNUMBER(T4)),NOT(ISNUMBER(U4)),NOT(ISNUMBER(Q4))),"待补充",IF(OR(Q4<0,Q4<>INT(Q4)),"检查输入",ROUND(Q4*T4-U4,4))))
R5: =IF(A5="","",IF(COUNT(G5,L5)<2,"待补充",IF(OR(G5<0,L5<0,L5>1),"检查输入",G5*L5))) | S5: =IF(A5="","",IF(COUNT(M5:N5)<2,"待补充",IF(OR(M5<0,M5>1,N5<0),"检查输入",M5*N5))) | T5: =IF(A5="","",IF(COUNT(F5:N5)<9,"待补充",IF(OR(MIN(F5:N5)<0,L5>1,M5>1),"检查输入",ROUND(F5-SUM(H5:K5)-R5-S5,4)))) | U5: =IF(A5="","",IF(COUNT(O5:P5)<2,"待补充",IF(MIN(O5:P5)<0,"检查输入",SUM(O5:P5)))) | V5: =IF(A5="","",IF(OR(T5="检查输入",U5="检查输入"),"检查输入",IF(OR(NOT(ISNUMBER(T5)),NOT(ISNUMBER(U5))),"待补充",IF(T5<=0,"不可保本",IFERROR(ROUNDUP(U5/T5,0),"检查输入"))))) | W5: =IF(A5="","",IF(OR(NOT(ISNUMBER(T5)),NOT(ISNUMBER(U5)),NOT(ISNUMBER(Q5))),"待补充",IF(OR(Q5<0,Q5<>INT(Q5)),"检查输入",ROUND(Q5*T5-U5,4))))
R6: =IF(A6="","",IF(COUNT(G6,L6)<2,"待补充",IF(OR(G6<0,L6<0,L6>1),"检查输入",G6*L6))) | S6: =IF(A6="","",IF(COUNT(M6:N6)<2,"待补充",IF(OR(M6<0,M6>1,N6<0),"检查输入",M6*N6))) | T6: =IF(A6="","",IF(COUNT(F6:N6)<9,"待补充",IF(OR(MIN(F6:N6)<0,L6>1,M6>1),"检查输入",ROUND(F6-SUM(H6:K6)-R6-S6,4)))) | U6: =IF(A6="","",IF(COUNT(O6:P6)<2,"待补充",IF(MIN(O6:P6)<0,"检查输入",SUM(O6:P6)))) | V6: =IF(A6="","",IF(OR(T6="检查输入",U6="检查输入"),"检查输入",IF(OR(NOT(ISNUMBER(T6)),NOT(ISNUMBER(U6))),"待补充",IF(T6<=0,"不可保本",IFERROR(ROUNDUP(U6/T6,0),"检查输入"))))) | W6: =IF(A6="","",IF(OR(NOT(ISNUMBER(T6)),NOT(ISNUMBER(U6)),NOT(ISNUMBER(Q6))),"待补充",IF(OR(Q6<0,Q6<>INT(Q6)),"检查输入",ROUND(Q6*T6-U6,4))))
R7: =IF(A7="","",IF(COUNT(G7,L7)<2,"待补充",IF(OR(G7<0,L7<0,L7>1),"检查输入",G7*L7))) | S7: =IF(A7="","",IF(COUNT(M7:N7)<2,"待补充",IF(OR(M7<0,M7>1,N7<0),"检查输入",M7*N7))) | T7: =IF(A7="","",IF(COUNT(F7:N7)<9,"待补充",IF(OR(MIN(F7:N7)<0,L7>1,M7>1),"检查输入",ROUND(F7-SUM(H7:K7)-R7-S7,4)))) | U7: =IF(A7="","",IF(COUNT(O7:P7)<2,"待补充",IF(MIN(O7:P7)<0,"检查输入",SUM(O7:P7)))) | V7: =IF(A7="","",IF(OR(T7="检查输入",U7="检查输入"),"检查输入",IF(OR(NOT(ISNUMBER(T7)),NOT(ISNUMBER(U7))),"待补充",IF(T7<=0,"不可保本",IFERROR(ROUNDUP(U7/T7,0),"检查输入"))))) | W7: =IF(A7="","",IF(OR(NOT(ISNUMBER(T7)),NOT(ISNUMBER(U7)),NOT(ISNUMBER(Q7))),"待补充",IF(OR(Q7<0,Q7<>INT(Q7)),"检查输入",ROUND(Q7*T7-U7,4))))
R8: =IF(A8="","",IF(COUNT(G8,L8)<2,"待补充",IF(OR(G8<0,L8<0,L8>1),"检查输入",G8*L8))) | S8: =IF(A8="","",IF(COUNT(M8:N8)<2,"待补充",IF(OR(M8<0,M8>1,N8<0),"检查输入",M8*N8))) | T8: =IF(A8="","",IF(COUNT(F8:N8)<9,"待补充",IF(OR(MIN(F8:N8)<0,L8>1,M8>1),"检查输入",ROUND(F8-SUM(H8:K8)-R8-S8,4)))) | U8: =IF(A8="","",IF(COUNT(O8:P8)<2,"待补充",IF(MIN(O8:P8)<0,"检查输入",SUM(O8:P8)))) | V8: =IF(A8="","",IF(OR(T8="检查输入",U8="检查输入"),"检查输入",IF(OR(NOT(ISNUMBER(T8)),NOT(ISNUMBER(U8))),"待补充",IF(T8<=0,"不可保本",IFERROR(ROUNDUP(U8/T8,0),"检查输入"))))) | W8: =IF(A8="","",IF(OR(NOT(ISNUMBER(T8)),NOT(ISNUMBER(U8)),NOT(ISNUMBER(Q8))),"待补充",IF(OR(Q8<0,Q8<>INT(Q8)),"检查输入",ROUND(Q8*T8-U8,4))))
R9: =IF(A9="","",IF(COUNT(G9,L9)<2,"待补充",IF(OR(G9<0,L9<0,L9>1),"检查输入",G9*L9))) | S9: =IF(A9="","",IF(COUNT(M9:N9)<2,"待补充",IF(OR(M9<0,M9>1,N9<0),"检查输入",M9*N9))) | T9: =IF(A9="","",IF(COUNT(F9:N9)<9,"待补充",IF(OR(MIN(F9:N9)<0,L9>1,M9>1),"检查输入",ROUND(F9-SUM(H9:K9)-R9-S9,4)))) | U9: =IF(A9="","",IF(COUNT(O9:P9)<2,"待补充",IF(MIN(O9:P9)<0,"检查输入",SUM(O9:P9)))) | V9: =IF(A9="","",IF(OR(T9="检查输入",U9="检查输入"),"检查输入",IF(OR(NOT(ISNUMBER(T9)),NOT(ISNUMBER(U9))),"待补充",IF(T9<=0,"不可保本",IFERROR(ROUNDUP(U9/T9,0),"检查输入"))))) | W9: =IF(A9="","",IF(OR(NOT(ISNUMBER(T9)),NOT(ISNUMBER(U9)),NOT(ISNUMBER(Q9))),"待补充",IF(OR(Q9<0,Q9<>INT(Q9)),"检查输入",ROUND(Q9*T9-U9,4))))
R10: =IF(A10="","",IF(COUNT(G10,L10)<2,"待补充",IF(OR(G10<0,L10<0,L10>1),"检查输入",G10*L10))) | S10: =IF(A10="","",IF(COUNT(M10:N10)<2,"待补充",IF(OR(M10<0,M10>1,N10<0),"检查输入",M10*N10))) | T10: =IF(A10="","",IF(COUNT(F10:N10)<9,"待补充",IF(OR(MIN(F10:N10)<0,L10>1,M10>1),"检查输入",ROUND(F10-SUM(H10:K10)-R10-S10,4)))) | U10: =IF(A10="","",IF(COUNT(O10:P10)<2,"待补充",IF(MIN(O10:P10)<0,"检查输入",SUM(O10:P10)))) | V10: =IF(A10="","",IF(OR(T10="检查输入",U10="检查输入"),"检查输入",IF(OR(NOT(ISNUMBER(T10)),NOT(ISNUMBER(U10))),"待补充",IF(T10<=0,"不可保本",IFERROR(ROUNDUP(U10/T10,0),"检查输入"))))) | W10: =IF(A10="","",IF(OR(NOT(ISNUMBER(T10)),NOT(ISNUMBER(U10)),NOT(ISNUMBER(Q10))),"待补充",IF(OR(Q10<0,Q10<>INT(Q10)),"检查输入",ROUND(Q10*T10-U10,4))))
R11: =IF(A11="","",IF(COUNT(G11,L11)<2,"待补充",IF(OR(G11<0,L11<0,L11>1),"检查输入",G11*L11))) | S11: =IF(A11="","",IF(COUNT(M11:N11)<2,"待补充",IF(OR(M11<0,M11>1,N11<0),"检查输入",M11*N11))) | T11: =IF(A11="","",IF(COUNT(F11:N11)<9,"待补充",IF(OR(MIN(F11:N11)<0,L11>1,M11>1),"检查输入",ROUND(F11-SUM(H11:K11)-R11-S11,4)))) | U11: =IF(A11="","",IF(COUNT(O11:P11)<2,"待补充",IF(MIN(O11:P11)<0,"检查输入",SUM(O11:P11)))) | V11: =IF(A11="","",IF(OR(T11="检查输入",U11="检查输入"),"检查输入",IF(OR(NOT(ISNUMBER(T11)),NOT(ISNUMBER(U11))),"待补充",IF(T11<=0,"不可保本",IFERROR(ROUNDUP(U11/T11,0),"检查输入"))))) | W11: =IF(A11="","",IF(OR(NOT(ISNUMBER(T11)),NOT(ISNUMBER(U11)),NOT(ISNUMBER(Q11))),"待补充",IF(OR(Q11<0,Q11<>INT(Q11)),"检查输入",ROUND(Q11*T11-U11,4))))
R12: =IF(A12="","",IF(COUNT(G12,L12)<2,"待补充",IF(OR(G12<0,L12<0,L12>1),"检查输入",G12*L12))) | S12: =IF(A12="","",IF(COUNT(M12:N12)<2,"待补充",IF(OR(M12<0,M12>1,N12<0),"检查输入",M12*N12))) | T12: =IF(A12="","",IF(COUNT(F12:N12)<9,"待补充",IF(OR(MIN(F12:N12)<0,L12>1,M12>1),"检查输入",ROUND(F12-SUM(H12:K12)-R12-S12,4)))) | U12: =IF(A12="","",IF(COUNT(O12:P12)<2,"待补充",IF(MIN(O12:P12)<0,"检查输入",SUM(O12:P12)))) | V12: =IF(A12="","",IF(OR(T12="检查输入",U12="检查输入"),"检查输入",IF(OR(NOT(ISNUMBER(T12)),NOT(ISNUMBER(U12))),"待补充",IF(T12<=0,"不可保本",IFERROR(ROUNDUP(U12/T12,0),"检查输入"))))) | W12: =IF(A12="","",IF(OR(NOT(ISNUMBER(T12)),NOT(ISNUMBER(U12)),NOT(ISNUMBER(Q12))),"待补充",IF(OR(Q12<0,Q12<>INT(Q12)),"检查输入",ROUND(Q12*T12-U12,4))))
R13: =IF(A13="","",IF(COUNT(G13,L13)<2,"待补充",IF(OR(G13<0,L13<0,L13>1),"检查输入",G13*L13))) | S13: =IF(A13="","",IF(COUNT(M13:N13)<2,"待补充",IF(OR(M13<0,M13>1,N13<0),"检查输入",M13*N13))) | T13: =IF(A13="","",IF(COUNT(F13:N13)<9,"待补充",IF(OR(MIN(F13:N13)<0,L13>1,M13>1),"检查输入",ROUND(F13-SUM(H13:K13)-R13-S13,4)))) | U13: =IF(A13="","",IF(COUNT(O13:P13)<2,"待补充",IF(MIN(O13:P13)<0,"检查输入",SUM(O13:P13)))) | V13: =IF(A13="","",IF(OR(T13="检查输入",U13="检查输入"),"检查输入",IF(OR(NOT(ISNUMBER(T13)),NOT(ISNUMBER(U13))),"待补充",IF(T13<=0,"不可保本",IFERROR(ROUNDUP(U13/T13,0),"检查输入"))))) | W13: =IF(A13="","",IF(OR(NOT(ISNUMBER(T13)),NOT(ISNUMBER(U13)),NOT(ISNUMBER(Q13))),"待补充",IF(OR(Q13<0,Q13<>INT(Q13)),"检查输入",ROUND(Q13*T13-U13,4))))
... R301: =IF(A301="","",IF(COUNT(G301,L301)<2,"待补充",IF(OR(G301<0,L301<0,L301>1),"检查输入",G301*L301))) | S301: =IF(A301="","",IF(COUNT(M301:N301)<2,"待补充",IF(OR(M301<0,M301>1,N301<0),"检查输入",M301*N301))) | T301: =IF(A301="","",IF(COUNT(F301:N301)<9,"待补充",IF(OR(MIN(F301:N301)<0,L301>1,M301>1),"检查输入",ROUND(F301-SUM(H301:K301)-R301-S301,4)))) | U301: =IF(A301="","",IF(COUNT(O301:P301)<2,"待补充",IF(MIN(O301:P301)<0,"检查输入",SUM(O301:P301)))) | V301: =IF(A301="","",IF(OR(T301="检查输入",U301="检查输入"),"检查输入",IF(OR(NOT(ISNUMBER(T301)),NOT(ISNUMBER(U301))),"待补充",IF(T301<=0,"不可保本",IFERROR(ROUNDUP(U301/T301,0),"检查输入"))))) | W301: =IF(A301="","",IF(OR(NOT(ISNUMBER(T301)),NOT(ISNUMBER(U301)),NOT(ISNUMBER(Q301))),"待补充",IF(OR(Q301<0,Q301<>INT(Q301)),"检查输入",ROUND(Q301*T301-U301,4))))

Sheet 每周漏斗
A1: 周起始日期（手填） | B1: 负责人（空=全部） | C1: 周截止（不含，自动） | D1: 新增线索 | E1: 首次触达 | F1: 达成合作 | G1: 寄出样品单 | H1: 签收样品单 | I1: 发布视频数（去重） | J1: 本周发片队列已核实净收入 | K1: 本周发片队列贡献估算 | L1: 本周寄出样品投入 | M1: 本周主要问题 / 下周动作 | N1: 复盘负责人 | O1: 复盘日期 | P1: 下次检查日期
C2: =IF(A2="","",A2+7) | D2: =IF($A2="","",IF($B2="",COUNTIFS('达人线索与合作'!$A$2:$A$301,"<>",'达人线索与合作'!$U$2:$U$301,">="&$A2,'达人线索与合作'!$U$2:$U$301,"<"&$C2),COUNTIFS('达人线索与合作'!$A$2:$A$301,"<>",'达人线索与合作'!$U$2:$U$301,">="&$A2,'达人线索与合作'!$U$2:$U$301,"<"&$C2,'达人线索与合作'!$F$2:$F$301,$B2))) | E2: =IF($A2="","",IF($B2="",COUNTIFS('达人线索与合作'!$A$2:$A$301,"<>",'达人线索与合作'!$AC$2:$AC$301,">="&$A2,'达人线索与合作'!$AC$2:$AC$301,"<"&$C2),COUNTIFS('达人线索与合作'!$A$2:$A$301,"<>",'达人线索与合作'!$AC$2:$AC$301,">="&$A2,'达人线索与合作'!$AC$2:$AC$301,"<"&$C2,'达人线索与合作'!$F$2:$F$301,$B2))) | F2: =IF($A2="","",IF($B2="",COUNTIFS('达人线索与合作'!$B$2:$B$301,"<>",'达人线索与合作'!$AD$2:$AD$301,">="&$A2,'达人线索与合作'!$AD$2:$AD$301,"<"&$C2),COUNTIFS('达人线索与合作'!$B$2:$B$301,"<>",'达人线索与合作'!$AD$2:$AD$301,">="&$A2,'达人线索与合作'!$AD$2:$AD$301,"<"&$C2,'达人线索与合作'!$F$2:$F$301,$B2))) | G2: =IF($A2="","",IF($B2="",COUNTIFS('寄样履约'!$A$2:$A$301,"<>",'寄样履约'!$H$2:$H$301,">="&$A2,'寄样履约'!$H$2:$H$301,"<"&$C2),COUNTIFS('寄样履约'!$A$2:$A$301,"<>",'寄样履约'!$H$2:$H$301,">="&$A2,'寄样履约'!$H$2:$H$301,"<"&$C2,'寄样履约'!$D$2:$D$301,$B2))) | H2: =IF($A2="","",IF($B2="",COUNTIFS('寄样履约'!$A$2:$A$301,"<>",'寄样履约'!$K$2:$K$301,">="&$A2,'寄样履约'!$K$2:$K$301,"<"&$C2),COUNTIFS('寄样履约'!$A$2:$A$301,"<>",'寄样履约'!$K$2:$K$301,">="&$A2,'寄样履约'!$K$2:$K$301,"<"&$C2,'寄样履约'!$D$2:$D$301,$B2))) | I2: =IF($A2="","",IF($B2="",SUMIFS('视频与订单复盘'!$AG$2:$AG$301,'视频与订单复盘'!$I$2:$I$301,">="&$A2,'视频与订单复盘'!$I$2:$I$301,"<"&$C2),SUMIFS('视频与订单复盘'!$AG$2:$AG$301,'视频与订单复盘'!$I$2:$I$301,">="&$A2,'视频与订单复盘'!$I$2:$I$301,"<"&$C2,'视频与订单复盘'!$H$2:$H$301,$B2))) | J2: =IF($A2="","",IF($B2="",SUMIFS('视频与订单复盘'!$P$2:$P$301,'视频与订单复盘'!$I$2:$I$301,">="&$A2,'视频与订单复盘'!$I$2:$I$301,"<"&$C2,'视频与订单复盘'!$AF$2:$AF$301,"可汇总"),SUMIFS('视频与订单复盘'!$P$2:$P$301,'视频与订单复盘'!$I$2:$I$301,">="&$A2,'视频与订单复盘'!$I$2:$I$301,"<"&$C2,'视频与订单复盘'!$AF$2:$AF$301,"可汇总",'视频与订单复盘'!$H$2:$H$301,$B2))) | K2: =IF($A2="","",IF($B2="",SUMIFS('视频与订单复盘'!$Y$2:$Y$301,'视频与订单复盘'!$I$2:$I$301,">="&$A2,'视频与订单复盘'!$I$2:$I$301,"<"&$C2,'视频与订单复盘'!$AF$2:$AF$301,"可汇总"),SUMIFS('视频与订单复盘'!$Y$2:$Y$301,'视频与订单复盘'!$I$2:$I$301,">="&$A2,'视频与订单复盘'!$I$2:$I$301,"<"&$C2,'视频与订单复盘'!$AF$2:$AF$301,"可汇总",'视频与订单复盘'!$H$2:$H$301,$B2))) | L2: =IF($A2="","",IF($B2="",SUMIFS('寄样履约'!$R$2:$R$301,'寄样履约'!$A$2:$A$301,"<>",'寄样履约'!$H$2:$H$301,">="&$A2,'寄样履约'!$H$2:$H$301,"<"&$C2),SUMIFS('寄样履约'!$R$2:$R$301,'寄样履约'!$A$2:$A$301,"<>",'寄样履约'!$H$2:$H$301,">="&$A2,'寄样履约'!$H$2:$H$301,"<"&$C2,'寄样履约'!$D$2:$D$301,$B2)))
C3: =IF(A3="","",A3+7) | D3: =IF($A3="","",IF($B3="",COUNTIFS('达人线索与合作'!$A$2:$A$301,"<>",'达人线索与合作'!$U$2:$U$301,">="&$A3,'达人线索与合作'!$U$2:$U$301,"<"&$C3),COUNTIFS('达人线索与合作'!$A$2:$A$301,"<>",'达人线索与合作'!$U$2:$U$301,">="&$A3,'达人线索与合作'!$U$2:$U$301,"<"&$C3,'达人线索与合作'!$F$2:$F$301,$B3))) | E3: =IF($A3="","",IF($B3="",COUNTIFS('达人线索与合作'!$A$2:$A$301,"<>",'达人线索与合作'!$AC$2:$AC$301,">="&$A3,'达人线索与合作'!$AC$2:$AC$301,"<"&$C3),COUNTIFS('达人线索与合作'!$A$2:$A$301,"<>",'达人线索与合作'!$AC$2:$AC$301,">="&$A3,'达人线索与合作'!$AC$2:$AC$301,"<"&$C3,'达人线索与合作'!$F$2:$F$301,$B3))) | F3: =IF($A3="","",IF($B3="",COUNTIFS('达人线索与合作'!$B$2:$B$301,"<>",'达人线索与合作'!$AD$2:$AD$301,">="&$A3,'达人线索与合作'!$AD$2:$AD$301,"<"&$C3),COUNTIFS('达人线索与合作'!$B$2:$B$301,"<>",'达人线索与合作'!$AD$2:$AD$301,">="&$A3,'达人线索与合作'!$AD$2:$AD$301,"<"&$C3,'达人线索与合作'!$F$2:$F$301,$B3))) | G3: =IF($A3="","",IF($B3="",COUNTIFS('寄样履约'!$A$2:$A$301,"<>",'寄样履约'!$H$2:$H$301,">="&$A3,'寄样履约'!$H$2:$H$301,"<"&$C3),COUNTIFS('寄样履约'!$A$2:$A$301,"<>",'寄样履约'!$H$2:$H$301,">="&$A3,'寄样履约'!$H$2:$H$301,"<"&$C3,'寄样履约'!$D$2:$D$301,$B3))) | H3: =IF($A3="","",IF($B3="",COUNTIFS('寄样履约'!$A$2:$A$301,"<>",'寄样履约'!$K$2:$K$301,">="&$A3,'寄样履约'!$K$2:$K$301,"<"&$C3),COUNTIFS('寄样履约'!$A$2:$A$301,"<>",'寄样履约'!$K$2:$K$301,">="&$A3,'寄样履约'!$K$2:$K$301,"<"&$C3,'寄样履约'!$D$2:$D$301,$B3))) | I3: =IF($A3="","",IF($B3="",SUMIFS('视频与订单复盘'!$AG$2:$AG$301,'视频与订单复盘'!$I$2:$I$301,">="&$A3,'视频与订单复盘'!$I$2:$I$301,"<"&$C3),SUMIFS('视频与订单复盘'!$AG$2:$AG$301,'视频与订单复盘'!$I$2:$I$301,">="&$A3,'视频与订单复盘'!$I$2:$I$301,"<"&$C3,'视频与订单复盘'!$H$2:$H$301,$B3))) | J3: =IF($A3="","",IF($B3="",SUMIFS('视频与订单复盘'!$P$2:$P$301,'视频与订单复盘'!$I$2:$I$301,">="&$A3,'视频与订单复盘'!$I$2:$I$301,"<"&$C3,'视频与订单复盘'!$AF$2:$AF$301,"可汇总"),SUMIFS('视频与订单复盘'!$P$2:$P$301,'视频与订单复盘'!$I$2:$I$301,">="&$A3,'视频与订单复盘'!$I$2:$I$301,"<"&$C3,'视频与订单复盘'!$AF$2:$AF$301,"可汇总",'视频与订单复盘'!$H$2:$H$301,$B3))) | K3: =IF($A3="","",IF($B3="",SUMIFS('视频与订单复盘'!$Y$2:$Y$301,'视频与订单复盘'!$I$2:$I$301,">="&$A3,'视频与订单复盘'!$I$2:$I$301,"<"&$C3,'视频与订单复盘'!$AF$2:$AF$301,"可汇总"),SUMIFS('视频与订单复盘'!$Y$2:$Y$301,'视频与订单复盘'!$I$2:$I$301,">="&$A3,'视频与订单复盘'!$I$2:$I$301,"<"&$C3,'视频与订单复盘'!$AF$2:$AF$301,"可汇总",'视频与订单复盘'!$H$2:$H$301,$B3))) | L3: =IF($A3="","",IF($B3="",SUMIFS('寄样履约'!$R$2:$R$301,'寄样履约'!$A$2:$A$301,"<>",'寄样履约'!$H$2:$H$301,">="&$A3,'寄样履约'!$H$2:$H$301,"<"&$C3),SUMIFS('寄样履约'!$R$2:$R$301,'寄样履约'!$A$2:$A$301,"<>",'寄样履约'!$H$2:$H$301,">="&$A3,'寄样履约'!$H$2:$H$301,"<"&$C3,'寄样履约'!$D$2:$D$301,$B3)))
C4: =IF(A4="","",A4+7) | D4: =IF($A4="","",IF($B4="",COUNTIFS('达人线索与合作'!$A$2:$A$301,"<>",'达人线索与合作'!$U$2:$U$301,">="&$A4,'达人线索与合作'!$U$2:$U$301,"<"&$C4),COUNTIFS('达人线索与合作'!$A$2:$A$301,"<>",'达人线索与合作'!$U$2:$U$301,">="&$A4,'达人线索与合作'!$U$2:$U$301,"<"&$C4,'达人线索与合作'!$F$2:$F$301,$B4))) | E4: =IF($A4="","",IF($B4="",COUNTIFS('达人线索与合作'!$A$2:$A$301,"<>",'达人线索与合作'!$AC$2:$AC$301,">="&$A4,'达人线索与合作'!$AC$2:$AC$301,"<"&$C4),COUNTIFS('达人线索与合作'!$A$2:$A$301,"<>",'达人线索与合作'!$AC$2:$AC$301,">="&$A4,'达人线索与合作'!$AC$2:$AC$301,"<"&$C4,'达人线索与合作'!$F$2:$F$301,$B4))) | F4: =IF($A4="","",IF($B4="",COUNTIFS('达人线索与合作'!$B$2:$B$301,"<>",'达人线索与合作'!$AD$2:$AD$301,">="&$A4,'达人线索与合作'!$AD$2:$AD$301,"<"&$C4),COUNTIFS('达人线索与合作'!$B$2:$B$301,"<>",'达人线索与合作'!$AD$2:$AD$301,">="&$A4,'达人线索与合作'!$AD$2:$AD$301,"<"&$C4,'达人线索与合作'!$F$2:$F$301,$B4))) | G4: =IF($A4="","",IF($B4="",COUNTIFS('寄样履约'!$A$2:$A$301,"<>",'寄样履约'!$H$2:$H$301,">="&$A4,'寄样履约'!$H$2:$H$301,"<"&$C4),COUNTIFS('寄样履约'!$A$2:$A$301,"<>",'寄样履约'!$H$2:$H$301,">="&$A4,'寄样履约'!$H$2:$H$301,"<"&$C4,'寄样履约'!$D$2:$D$301,$B4))) | H4: =IF($A4="","",IF($B4="",COUNTIFS('寄样履约'!$A$2:$A$301,"<>",'寄样履约'!$K$2:$K$301,">="&$A4,'寄样履约'!$K$2:$K$301,"<"&$C4),COUNTIFS('寄样履约'!$A$2:$A$301,"<>",'寄样履约'!$K$2:$K$301,">="&$A4,'寄样履约'!$K$2:$K$301,"<"&$C4,'寄样履约'!$D$2:$D$301,$B4))) | I4: =IF($A4="","",IF($B4="",SUMIFS('视频与订单复盘'!$AG$2:$AG$301,'视频与订单复盘'!$I$2:$I$301,">="&$A4,'视频与订单复盘'!$I$2:$I$301,"<"&$C4),SUMIFS('视频与订单复盘'!$AG$2:$AG$301,'视频与订单复盘'!$I$2:$I$301,">="&$A4,'视频与订单复盘'!$I$2:$I$301,"<"&$C4,'视频与订单复盘'!$H$2:$H$301,$B4))) | J4: =IF($A4="","",IF($B4="",SUMIFS('视频与订单复盘'!$P$2:$P$301,'视频与订单复盘'!$I$2:$I$301,">="&$A4,'视频与订单复盘'!$I$2:$I$301,"<"&$C4,'视频与订单复盘'!$AF$2:$AF$301,"可汇总"),SUMIFS('视频与订单复盘'!$P$2:$P$301,'视频与订单复盘'!$I$2:$I$301,">="&$A4,'视频与订单复盘'!$I$2:$I$301,"<"&$C4,'视频与订单复盘'!$AF$2:$AF$301,"可汇总",'视频与订单复盘'!$H$2:$H$301,$B4))) | K4: =IF($A4="","",IF($B4="",SUMIFS('视频与订单复盘'!$Y$2:$Y$301,'视频与订单复盘'!$I$2:$I$301,">="&$A4,'视频与订单复盘'!$I$2:$I$301,"<"&$C4,'视频与订单复盘'!$AF$2:$AF$301,"可汇总"),SUMIFS('视频与订单复盘'!$Y$2:$Y$301,'视频与订单复盘'!$I$2:$I$301,">="&$A4,'视频与订单复盘'!$I$2:$I$301,"<"&$C4,'视频与订单复盘'!$AF$2:$AF$301,"可汇总",'视频与订单复盘'!$H$2:$H$301,$B4))) | L4: =IF($A4="","",IF($B4="",SUMIFS('寄样履约'!$R$2:$R$301,'寄样履约'!$A$2:$A$301,"<>",'寄样履约'!$H$2:$H$301,">="&$A4,'寄样履约'!$H$2:$H$301,"<"&$C4),SUMIFS('寄样履约'!$R$2:$R$301,'寄样履约'!$A$2:$A$301,"<>",'寄样履约'!$H$2:$H$301,">="&$A4,'寄样履约'!$H$2:$H$301,"<"&$C4,'寄样履约'!$D$2:$D$301,$B4)))
C5: =IF(A5="","",A5+7) | D5: =IF($A5="","",IF($B5="",COUNTIFS('达人线索与合作'!$A$2:$A$301,"<>",'达人线索与合作'!$U$2:$U$301,">="&$A5,'达人线索与合作'!$U$2:$U$301,"<"&$C5),COUNTIFS('达人线索与合作'!$A$2:$A$301,"<>",'达人线索与合作'!$U$2:$U$301,">="&$A5,'达人线索与合作'!$U$2:$U$301,"<"&$C5,'达人线索与合作'!$F$2:$F$301,$B5))) | E5: =IF($A5="","",IF($B5="",COUNTIFS('达人线索与合作'!$A$2:$A$301,"<>",'达人线索与合作'!$AC$2:$AC$301,">="&$A5,'达人线索与合作'!$AC$2:$AC$301,"<"&$C5),COUNTIFS('达人线索与合作'!$A$2:$A$301,"<>",'达人线索与合作'!$AC$2:$AC$301,">="&$A5,'达人线索与合作'!$AC$2:$AC$301,"<"&$C5,'达人线索与合作'!$F$2:$F$301,$B5))) | F5: =IF($A5="","",IF($B5="",COUNTIFS('达人线索与合作'!$B$2:$B$301,"<>",'达人线索与合作'!$AD$2:$AD$301,">="&$A5,'达人线索与合作'!$AD$2:$AD$301,"<"&$C5),COUNTIFS('达人线索与合作'!$B$2:$B$301,"<>",'达人线索与合作'!$AD$2:$AD$301,">="&$A5,'达人线索与合作'!$AD$2:$AD$301,"<"&$C5,'达人线索与合作'!$F$2:$F$301,$B5))) | G5: =IF($A5="","",IF($B5="",COUNTIFS('寄样履约'!$A$2:$A$301,"<>",'寄样履约'!$H$2:$H$301,">="&$A5,'寄样履约'!$H$2:$H$301,"<"&$C5),COUNTIFS('寄样履约'!$A$2:$A$301,"<>",'寄样履约'!$H$2:$H$301,">="&$A5,'寄样履约'!$H$2:$H$301,"<"&$C5,'寄样履约'!$D$2:$D$301,$B5))) | H5: =IF($A5="","",IF($B5="",COUNTIFS('寄样履约'!$A$2:$A$301,"<>",'寄样履约'!$K$2:$K$301,">="&$A5,'寄样履约'!$K$2:$K$301,"<"&$C5),COUNTIFS('寄样履约'!$A$2:$A$301,"<>",'寄样履约'!$K$2:$K$301,">="&$A5,'寄样履约'!$K$2:$K$301,"<"&$C5,'寄样履约'!$D$2:$D$301,$B5))) | I5: =IF($A5="","",IF($B5="",SUMIFS('视频与订单复盘'!$AG$2:$AG$301,'视频与订单复盘'!$I$2:$I$301,">="&$A5,'视频与订单复盘'!$I$2:$I$301,"<"&$C5),SUMIFS('视频与订单复盘'!$AG$2:$AG$301,'视频与订单复盘'!$I$2:$I$301,">="&$A5,'视频与订单复盘'!$I$2:$I$301,"<"&$C5,'视频与订单复盘'!$H$2:$H$301,$B5))) | J5: =IF($A5="","",IF($B5="",SUMIFS('视频与订单复盘'!$P$2:$P$301,'视频与订单复盘'!$I$2:$I$301,">="&$A5,'视频与订单复盘'!$I$2:$I$301,"<"&$C5,'视频与订单复盘'!$AF$2:$AF$301,"可汇总"),SUMIFS('视频与订单复盘'!$P$2:$P$301,'视频与订单复盘'!$I$2:$I$301,">="&$A5,'视频与订单复盘'!$I$2:$I$301,"<"&$C5,'视频与订单复盘'!$AF$2:$AF$301,"可汇总",'视频与订单复盘'!$H$2:$H$301,$B5))) | K5: =IF($A5="","",IF($B5="",SUMIFS('视频与订单复盘'!$Y$2:$Y$301,'视频与订单复盘'!$I$2:$I$301,">="&$A5,'视频与订单复盘'!$I$2:$I$301,"<"&$C5,'视频与订单复盘'!$AF$2:$AF$301,"可汇总"),SUMIFS('视频与订单复盘'!$Y$2:$Y$301,'视频与订单复盘'!$I$2:$I$301,">="&$A5,'视频与订单复盘'!$I$2:$I$301,"<"&$C5,'视频与订单复盘'!$AF$2:$AF$301,"可汇总",'视频与订单复盘'!$H$2:$H$301,$B5))) | L5: =IF($A5="","",IF($B5="",SUMIFS('寄样履约'!$R$2:$R$301,'寄样履约'!$A$2:$A$301,"<>",'寄样履约'!$H$2:$H$301,">="&$A5,'寄样履约'!$H$2:$H$301,"<"&$C5),SUMIFS('寄样履约'!$R$2:$R$301,'寄样履约'!$A$2:$A$301,"<>",'寄样履约'!$H$2:$H$301,">="&$A5,'寄样履约'!$H$2:$H$301,"<"&$C5,'寄样履约'!$D$2:$D$301,$B5)))
C6: =IF(A6="","",A6+7) | D6: =IF($A6="","",IF($B6="",COUNTIFS('达人线索与合作'!$A$2:$A$301,"<>",'达人线索与合作'!$U$2:$U$301,">="&$A6,'达人线索与合作'!$U$2:$U$301,"<"&$C6),COUNTIFS('达人线索与合作'!$A$2:$A$301,"<>",'达人线索与合作'!$U$2:$U$301,">="&$A6,'达人线索与合作'!$U$2:$U$301,"<"&$C6,'达人线索与合作'!$F$2:$F$301,$B6))) | E6: =IF($A6="","",IF($B6="",COUNTIFS('达人线索与合作'!$A$2:$A$301,"<>",'达人线索与合作'!$AC$2:$AC$301,">="&$A6,'达人线索与合作'!$AC$2:$AC$301,"<"&$C6),COUNTIFS('达人线索与合作'!$A$2:$A$301,"<>",'达人线索与合作'!$AC$2:$AC$301,">="&$A6,'达人线索与合作'!$AC$2:$AC$301,"<"&$C6,'达人线索与合作'!$F$2:$F$301,$B6))) | F6: =IF($A6="","",IF($B6="",COUNTIFS('达人线索与合作'!$B$2:$B$301,"<>",'达人线索与合作'!$AD$2:$AD$301,">="&$A6,'达人线索与合作'!$AD$2:$AD$301,"<"&$C6),COUNTIFS('达人线索与合作'!$B$2:$B$301,"<>",'达人线索与合作'!$AD$2:$AD$301,">="&$A6,'达人线索与合作'!$AD$2:$AD$301,"<"&$C6,'达人线索与合作'!$F$2:$F$301,$B6))) | G6: =IF($A6="","",IF($B6="",COUNTIFS('寄样履约'!$A$2:$A$301,"<>",'寄样履约'!$H$2:$H$301,">="&$A6,'寄样履约'!$H$2:$H$301,"<"&$C6),COUNTIFS('寄样履约'!$A$2:$A$301,"<>",'寄样履约'!$H$2:$H$301,">="&$A6,'寄样履约'!$H$2:$H$301,"<"&$C6,'寄样履约'!$D$2:$D$301,$B6))) | H6: =IF($A6="","",IF($B6="",COUNTIFS('寄样履约'!$A$2:$A$301,"<>",'寄样履约'!$K$2:$K$301,">="&$A6,'寄样履约'!$K$2:$K$301,"<"&$C6),COUNTIFS('寄样履约'!$A$2:$A$301,"<>",'寄样履约'!$K$2:$K$301,">="&$A6,'寄样履约'!$K$2:$K$301,"<"&$C6,'寄样履约'!$D$2:$D$301,$B6))) | I6: =IF($A6="","",IF($B6="",SUMIFS('视频与订单复盘'!$AG$2:$AG$301,'视频与订单复盘'!$I$2:$I$301,">="&$A6,'视频与订单复盘'!$I$2:$I$301,"<"&$C6),SUMIFS('视频与订单复盘'!$AG$2:$AG$301,'视频与订单复盘'!$I$2:$I$301,">="&$A6,'视频与订单复盘'!$I$2:$I$301,"<"&$C6,'视频与订单复盘'!$H$2:$H$301,$B6))) | J6: =IF($A6="","",IF($B6="",SUMIFS('视频与订单复盘'!$P$2:$P$301,'视频与订单复盘'!$I$2:$I$301,">="&$A6,'视频与订单复盘'!$I$2:$I$301,"<"&$C6,'视频与订单复盘'!$AF$2:$AF$301,"可汇总"),SUMIFS('视频与订单复盘'!$P$2:$P$301,'视频与订单复盘'!$I$2:$I$301,">="&$A6,'视频与订单复盘'!$I$2:$I$301,"<"&$C6,'视频与订单复盘'!$AF$2:$AF$301,"可汇总",'视频与订单复盘'!$H$2:$H$301,$B6))) | K6: =IF($A6="","",IF($B6="",SUMIFS('视频与订单复盘'!$Y$2:$Y$301,'视频与订单复盘'!$I$2:$I$301,">="&$A6,'视频与订单复盘'!$I$2:$I$301,"<"&$C6,'视频与订单复盘'!$AF$2:$AF$301,"可汇总"),SUMIFS('视频与订单复盘'!$Y$2:$Y$301,'视频与订单复盘'!$I$2:$I$301,">="&$A6,'视频与订单复盘'!$I$2:$I$301,"<"&$C6,'视频与订单复盘'!$AF$2:$AF$301,"可汇总",'视频与订单复盘'!$H$2:$H$301,$B6))) | L6: =IF($A6="","",IF($B6="",SUMIFS('寄样履约'!$R$2:$R$301,'寄样履约'!$A$2:$A$301,"<>",'寄样履约'!$H$2:$H$301,">="&$A6,'寄样履约'!$H$2:$H$301,"<"&$C6),SUMIFS('寄样履约'!$R$2:$R$301,'寄样履约'!$A$2:$A$301,"<>",'寄样履约'!$H$2:$H$301,">="&$A6,'寄样履约'!$H$2:$H$301,"<"&$C6,'寄样履约'!$D$2:$D$301,$B6)))
C7: =IF(A7="","",A7+7) | D7: =IF($A7="","",IF($B7="",COUNTIFS('达人线索与合作'!$A$2:$A$301,"<>",'达人线索与合作'!$U$2:$U$301,">="&$A7,'达人线索与合作'!$U$2:$U$301,"<"&$C7),COUNTIFS('达人线索与合作'!$A$2:$A$301,"<>",'达人线索与合作'!$U$2:$U$301,">="&$A7,'达人线索与合作'!$U$2:$U$301,"<"&$C7,'达人线索与合作'!$F$2:$F$301,$B7))) | E7: =IF($A7="","",IF($B7="",COUNTIFS('达人线索与合作'!$A$2:$A$301,"<>",'达人线索与合作'!$AC$2:$AC$301,">="&$A7,'达人线索与合作'!$AC$2:$AC$301,"<"&$C7),COUNTIFS('达人线索与合作'!$A$2:$A$301,"<>",'达人线索与合作'!$AC$2:$AC$301,">="&$A7,'达人线索与合作'!$AC$2:$AC$301,"<"&$C7,'达人线索与合作'!$F$2:$F$301,$B7))) | F7: =IF($A7="","",IF($B7="",COUNTIFS('达人线索与合作'!$B$2:$B$301,"<>",'达人线索与合作'!$AD$2:$AD$301,">="&$A7,'达人线索与合作'!$AD$2:$AD$301,"<"&$C7),COUNTIFS('达人线索与合作'!$B$2:$B$301,"<>",'达人线索与合作'!$AD$2:$AD$301,">="&$A7,'达人线索与合作'!$AD$2:$AD$301,"<"&$C7,'达人线索与合作'!$F$2:$F$301,$B7))) | G7: =IF($A7="","",IF($B7="",COUNTIFS('寄样履约'!$A$2:$A$301,"<>",'寄样履约'!$H$2:$H$301,">="&$A7,'寄样履约'!$H$2:$H$301,"<"&$C7),COUNTIFS('寄样履约'!$A$2:$A$301,"<>",'寄样履约'!$H$2:$H$301,">="&$A7,'寄样履约'!$H$2:$H$301,"<"&$C7,'寄样履约'!$D$2:$D$301,$B7))) | H7: =IF($A7="","",IF($B7="",COUNTIFS('寄样履约'!$A$2:$A$301,"<>",'寄样履约'!$K$2:$K$301,">="&$A7,'寄样履约'!$K$2:$K$301,"<"&$C7),COUNTIFS('寄样履约'!$A$2:$A$301,"<>",'寄样履约'!$K$2:$K$301,">="&$A7,'寄样履约'!$K$2:$K$301,"<"&$C7,'寄样履约'!$D$2:$D$301,$B7))) | I7: =IF($A7="","",IF($B7="",SUMIFS('视频与订单复盘'!$AG$2:$AG$301,'视频与订单复盘'!$I$2:$I$301,">="&$A7,'视频与订单复盘'!$I$2:$I$301,"<"&$C7),SUMIFS('视频与订单复盘'!$AG$2:$AG$301,'视频与订单复盘'!$I$2:$I$301,">="&$A7,'视频与订单复盘'!$I$2:$I$301,"<"&$C7,'视频与订单复盘'!$H$2:$H$301,$B7))) | J7: =IF($A7="","",IF($B7="",SUMIFS('视频与订单复盘'!$P$2:$P$301,'视频与订单复盘'!$I$2:$I$301,">="&$A7,'视频与订单复盘'!$I$2:$I$301,"<"&$C7,'视频与订单复盘'!$AF$2:$AF$301,"可汇总"),SUMIFS('视频与订单复盘'!$P$2:$P$301,'视频与订单复盘'!$I$2:$I$301,">="&$A7,'视频与订单复盘'!$I$2:$I$301,"<"&$C7,'视频与订单复盘'!$AF$2:$AF$301,"可汇总",'视频与订单复盘'!$H$2:$H$301,$B7))) | K7: =IF($A7="","",IF($B7="",SUMIFS('视频与订单复盘'!$Y$2:$Y$301,'视频与订单复盘'!$I$2:$I$301,">="&$A7,'视频与订单复盘'!$I$2:$I$301,"<"&$C7,'视频与订单复盘'!$AF$2:$AF$301,"可汇总"),SUMIFS('视频与订单复盘'!$Y$2:$Y$301,'视频与订单复盘'!$I$2:$I$301,">="&$A7,'视频与订单复盘'!$I$2:$I$301,"<"&$C7,'视频与订单复盘'!$AF$2:$AF$301,"可汇总",'视频与订单复盘'!$H$2:$H$301,$B7))) | L7: =IF($A7="","",IF($B7="",SUMIFS('寄样履约'!$R$2:$R$301,'寄样履约'!$A$2:$A$301,"<>",'寄样履约'!$H$2:$H$301,">="&$A7,'寄样履约'!$H$2:$H$301,"<"&$C7),SUMIFS('寄样履约'!$R$2:$R$301,'寄样履约'!$A$2:$A$301,"<>",'寄样履约'!$H$2:$H$301,">="&$A7,'寄样履约'!$H$2:$H$301,"<"&$C7,'寄样履约'!$D$2:$D$301,$B7)))
C8: =IF(A8="","",A8+7) | D8: =IF($A8="","",IF($B8="",COUNTIFS('达人线索与合作'!$A$2:$A$301,"<>",'达人线索与合作'!$U$2:$U$301,">="&$A8,'达人线索与合作'!$U$2:$U$301,"<"&$C8),COUNTIFS('达人线索与合作'!$A$2:$A$301,"<>",'达人线索与合作'!$U$2:$U$301,">="&$A8,'达人线索与合作'!$U$2:$U$301,"<"&$C8,'达人线索与合作'!$F$2:$F$301,$B8))) | E8: =IF($A8="","",IF($B8="",COUNTIFS('达人线索与合作'!$A$2:$A$301,"<>",'达人线索与合作'!$AC$2:$AC$301,">="&$A8,'达人线索与合作'!$AC$2:$AC$301,"<"&$C8),COUNTIFS('达人线索与合作'!$A$2:$A$301,"<>",'达人线索与合作'!$AC$2:$AC$301,">="&$A8,'达人线索与合作'!$AC$2:$AC$301,"<"&$C8,'达人线索与合作'!$F$2:$F$301,$B8))) | F8: =IF($A8="","",IF($B8="",COUNTIFS('达人线索与合作'!$B$2:$B$301,"<>",'达人线索与合作'!$AD$2:$AD$301,">="&$A8,'达人线索与合作'!$AD$2:$AD$301,"<"&$C8),COUNTIFS('达人线索与合作'!$B$2:$B$301,"<>",'达人线索与合作'!$AD$2:$AD$301,">="&$A8,'达人线索与合作'!$AD$2:$AD$301,"<"&$C8,'达人线索与合作'!$F$2:$F$301,$B8))) | G8: =IF($A8="","",IF($B8="",COUNTIFS('寄样履约'!$A$2:$A$301,"<>",'寄样履约'!$H$2:$H$301,">="&$A8,'寄样履约'!$H$2:$H$301,"<"&$C8),COUNTIFS('寄样履约'!$A$2:$A$301,"<>",'寄样履约'!$H$2:$H$301,">="&$A8,'寄样履约'!$H$2:$H$301,"<"&$C8,'寄样履约'!$D$2:$D$301,$B8))) | H8: =IF($A8="","",IF($B8="",COUNTIFS('寄样履约'!$A$2:$A$301,"<>",'寄样履约'!$K$2:$K$301,">="&$A8,'寄样履约'!$K$2:$K$301,"<"&$C8),COUNTIFS('寄样履约'!$A$2:$A$301,"<>",'寄样履约'!$K$2:$K$301,">="&$A8,'寄样履约'!$K$2:$K$301,"<"&$C8,'寄样履约'!$D$2:$D$301,$B8))) | I8: =IF($A8="","",IF($B8="",SUMIFS('视频与订单复盘'!$AG$2:$AG$301,'视频与订单复盘'!$I$2:$I$301,">="&$A8,'视频与订单复盘'!$I$2:$I$301,"<"&$C8),SUMIFS('视频与订单复盘'!$AG$2:$AG$301,'视频与订单复盘'!$I$2:$I$301,">="&$A8,'视频与订单复盘'!$I$2:$I$301,"<"&$C8,'视频与订单复盘'!$H$2:$H$301,$B8))) | J8: =IF($A8="","",IF($B8="",SUMIFS('视频与订单复盘'!$P$2:$P$301,'视频与订单复盘'!$I$2:$I$301,">="&$A8,'视频与订单复盘'!$I$2:$I$301,"<"&$C8,'视频与订单复盘'!$AF$2:$AF$301,"可汇总"),SUMIFS('视频与订单复盘'!$P$2:$P$301,'视频与订单复盘'!$I$2:$I$301,">="&$A8,'视频与订单复盘'!$I$2:$I$301,"<"&$C8,'视频与订单复盘'!$AF$2:$AF$301,"可汇总",'视频与订单复盘'!$H$2:$H$301,$B8))) | K8: =IF($A8="","",IF($B8="",SUMIFS('视频与订单复盘'!$Y$2:$Y$301,'视频与订单复盘'!$I$2:$I$301,">="&$A8,'视频与订单复盘'!$I$2:$I$301,"<"&$C8,'视频与订单复盘'!$AF$2:$AF$301,"可汇总"),SUMIFS('视频与订单复盘'!$Y$2:$Y$301,'视频与订单复盘'!$I$2:$I$301,">="&$A8,'视频与订单复盘'!$I$2:$I$301,"<"&$C8,'视频与订单复盘'!$AF$2:$AF$301,"可汇总",'视频与订单复盘'!$H$2:$H$301,$B8))) | L8: =IF($A8="","",IF($B8="",SUMIFS('寄样履约'!$R$2:$R$301,'寄样履约'!$A$2:$A$301,"<>",'寄样履约'!$H$2:$H$301,">="&$A8,'寄样履约'!$H$2:$H$301,"<"&$C8),SUMIFS('寄样履约'!$R$2:$R$301,'寄样履约'!$A$2:$A$301,"<>",'寄样履约'!$H$2:$H$301,">="&$A8,'寄样履约'!$H$2:$H$301,"<"&$C8,'寄样履约'!$D$2:$D$301,$B8)))
C9: =IF(A9="","",A9+7) | D9: =IF($A9="","",IF($B9="",COUNTIFS('达人线索与合作'!$A$2:$A$301,"<>",'达人线索与合作'!$U$2:$U$301,">="&$A9,'达人线索与合作'!$U$2:$U$301,"<"&$C9),COUNTIFS('达人线索与合作'!$A$2:$A$301,"<>",'达人线索与合作'!$U$2:$U$301,">="&$A9,'达人线索与合作'!$U$2:$U$301,"<"&$C9,'达人线索与合作'!$F$2:$F$301,$B9))) | E9: =IF($A9="","",IF($B9="",COUNTIFS('达人线索与合作'!$A$2:$A$301,"<>",'达人线索与合作'!$AC$2:$AC$301,">="&$A9,'达人线索与合作'!$AC$2:$AC$301,"<"&$C9),COUNTIFS('达人线索与合作'!$A$2:$A$301,"<>",'达人线索与合作'!$AC$2:$AC$301,">="&$A9,'达人线索与合作'!$AC$2:$AC$301,"<"&$C9,'达人线索与合作'!$F$2:$F$301,$B9))) | F9: =IF($A9="","",IF($B9="",COUNTIFS('达人线索与合作'!$B$2:$B$301,"<>",'达人线索与合作'!$AD$2:$AD$301,">="&$A9,'达人线索与合作'!$AD$2:$AD$301,"<"&$C9),COUNTIFS('达人线索与合作'!$B$2:$B$301,"<>",'达人线索与合作'!$AD$2:$AD$301,">="&$A9,'达人线索与合作'!$AD$2:$AD$301,"<"&$C9,'达人线索与合作'!$F$2:$F$301,$B9))) | G9: =IF($A9="","",IF($B9="",COUNTIFS('寄样履约'!$A$2:$A$301,"<>",'寄样履约'!$H$2:$H$301,">="&$A9,'寄样履约'!$H$2:$H$301,"<"&$C9),COUNTIFS('寄样履约'!$A$2:$A$301,"<>",'寄样履约'!$H$2:$H$301,">="&$A9,'寄样履约'!$H$2:$H$301,"<"&$C9,'寄样履约'!$D$2:$D$301,$B9))) | H9: =IF($A9="","",IF($B9="",COUNTIFS('寄样履约'!$A$2:$A$301,"<>",'寄样履约'!$K$2:$K$301,">="&$A9,'寄样履约'!$K$2:$K$301,"<"&$C9),COUNTIFS('寄样履约'!$A$2:$A$301,"<>",'寄样履约'!$K$2:$K$301,">="&$A9,'寄样履约'!$K$2:$K$301,"<"&$C9,'寄样履约'!$D$2:$D$301,$B9))) | I9: =IF($A9="","",IF($B9="",SUMIFS('视频与订单复盘'!$AG$2:$AG$301,'视频与订单复盘'!$I$2:$I$301,">="&$A9,'视频与订单复盘'!$I$2:$I$301,"<"&$C9),SUMIFS('视频与订单复盘'!$AG$2:$AG$301,'视频与订单复盘'!$I$2:$I$301,">="&$A9,'视频与订单复盘'!$I$2:$I$301,"<"&$C9,'视频与订单复盘'!$H$2:$H$301,$B9))) | J9: =IF($A9="","",IF($B9="",SUMIFS('视频与订单复盘'!$P$2:$P$301,'视频与订单复盘'!$I$2:$I$301,">="&$A9,'视频与订单复盘'!$I$2:$I$301,"<"&$C9,'视频与订单复盘'!$AF$2:$AF$301,"可汇总"),SUMIFS('视频与订单复盘'!$P$2:$P$301,'视频与订单复盘'!$I$2:$I$301,">="&$A9,'视频与订单复盘'!$I$2:$I$301,"<"&$C9,'视频与订单复盘'!$AF$2:$AF$301,"可汇总",'视频与订单复盘'!$H$2:$H$301,$B9))) | K9: =IF($A9="","",IF($B9="",SUMIFS('视频与订单复盘'!$Y$2:$Y$301,'视频与订单复盘'!$I$2:$I$301,">="&$A9,'视频与订单复盘'!$I$2:$I$301,"<"&$C9,'视频与订单复盘'!$AF$2:$AF$301,"可汇总"),SUMIFS('视频与订单复盘'!$Y$2:$Y$301,'视频与订单复盘'!$I$2:$I$301,">="&$A9,'视频与订单复盘'!$I$2:$I$301,"<"&$C9,'视频与订单复盘'!$AF$2:$AF$301,"可汇总",'视频与订单复盘'!$H$2:$H$301,$B9))) | L9: =IF($A9="","",IF($B9="",SUMIFS('寄样履约'!$R$2:$R$301,'寄样履约'!$A$2:$A$301,"<>",'寄样履约'!$H$2:$H$301,">="&$A9,'寄样履约'!$H$2:$H$301,"<"&$C9),SUMIFS('寄样履约'!$R$2:$R$301,'寄样履约'!$A$2:$A$301,"<>",'寄样履约'!$H$2:$H$301,">="&$A9,'寄样履约'!$H$2:$H$301,"<"&$C9,'寄样履约'!$D$2:$D$301,$B9)))
C10: =IF(A10="","",A10+7) | D10: =IF($A10="","",IF($B10="",COUNTIFS('达人线索与合作'!$A$2:$A$301,"<>",'达人线索与合作'!$U$2:$U$301,">="&$A10,'达人线索与合作'!$U$2:$U$301,"<"&$C10),COUNTIFS('达人线索与合作'!$A$2:$A$301,"<>",'达人线索与合作'!$U$2:$U$301,">="&$A10,'达人线索与合作'!$U$2:$U$301,"<"&$C10,'达人线索与合作'!$F$2:$F$301,$B10))) | E10: =IF($A10="","",IF($B10="",COUNTIFS('达人线索与合作'!$A$2:$A$301,"<>",'达人线索与合作'!$AC$2:$AC$301,">="&$A10,'达人线索与合作'!$AC$2:$AC$301,"<"&$C10),COUNTIFS('达人线索与合作'!$A$2:$A$301,"<>",'达人线索与合作'!$AC$2:$AC$301,">="&$A10,'达人线索与合作'!$AC$2:$AC$301,"<"&$C10,'达人线索与合作'!$F$2:$F$301,$B10))) | F10: =IF($A10="","",IF($B10="",COUNTIFS('达人线索与合作'!$B$2:$B$301,"<>",'达人线索与合作'!$AD$2:$AD$301,">="&$A10,'达人线索与合作'!$AD$2:$AD$301,"<"&$C10),COUNTIFS('达人线索与合作'!$B$2:$B$301,"<>",'达人线索与合作'!$AD$2:$AD$301,">="&$A10,'达人线索与合作'!$AD$2:$AD$301,"<"&$C10,'达人线索与合作'!$F$2:$F$301,$B10))) | G10: =IF($A10="","",IF($B10="",COUNTIFS('寄样履约'!$A$2:$A$301,"<>",'寄样履约'!$H$2:$H$301,">="&$A10,'寄样履约'!$H$2:$H$301,"<"&$C10),COUNTIFS('寄样履约'!$A$2:$A$301,"<>",'寄样履约'!$H$2:$H$301,">="&$A10,'寄样履约'!$H$2:$H$301,"<"&$C10,'寄样履约'!$D$2:$D$301,$B10))) | H10: =IF($A10="","",IF($B10="",COUNTIFS('寄样履约'!$A$2:$A$301,"<>",'寄样履约'!$K$2:$K$301,">="&$A10,'寄样履约'!$K$2:$K$301,"<"&$C10),COUNTIFS('寄样履约'!$A$2:$A$301,"<>",'寄样履约'!$K$2:$K$301,">="&$A10,'寄样履约'!$K$2:$K$301,"<"&$C10,'寄样履约'!$D$2:$D$301,$B10))) | I10: =IF($A10="","",IF($B10="",SUMIFS('视频与订单复盘'!$AG$2:$AG$301,'视频与订单复盘'!$I$2:$I$301,">="&$A10,'视频与订单复盘'!$I$2:$I$301,"<"&$C10),SUMIFS('视频与订单复盘'!$AG$2:$AG$301,'视频与订单复盘'!$I$2:$I$301,">="&$A10,'视频与订单复盘'!$I$2:$I$301,"<"&$C10,'视频与订单复盘'!$H$2:$H$301,$B10))) | J10: =IF($A10="","",IF($B10="",SUMIFS('视频与订单复盘'!$P$2:$P$301,'视频与订单复盘'!$I$2:$I$301,">="&$A10,'视频与订单复盘'!$I$2:$I$301,"<"&$C10,'视频与订单复盘'!$AF$2:$AF$301,"可汇总"),SUMIFS('视频与订单复盘'!$P$2:$P$301,'视频与订单复盘'!$I$2:$I$301,">="&$A10,'视频与订单复盘'!$I$2:$I$301,"<"&$C10,'视频与订单复盘'!$AF$2:$AF$301,"可汇总",'视频与订单复盘'!$H$2:$H$301,$B10))) | K10: =IF($A10="","",IF($B10="",SUMIFS('视频与订单复盘'!$Y$2:$Y$301,'视频与订单复盘'!$I$2:$I$301,">="&$A10,'视频与订单复盘'!$I$2:$I$301,"<"&$C10,'视频与订单复盘'!$AF$2:$AF$301,"可汇总"),SUMIFS('视频与订单复盘'!$Y$2:$Y$301,'视频与订单复盘'!$I$2:$I$301,">="&$A10,'视频与订单复盘'!$I$2:$I$301,"<"&$C10,'视频与订单复盘'!$AF$2:$AF$301,"可汇总",'视频与订单复盘'!$H$2:$H$301,$B10))) | L10: =IF($A10="","",IF($B10="",SUMIFS('寄样履约'!$R$2:$R$301,'寄样履约'!$A$2:$A$301,"<>",'寄样履约'!$H$2:$H$301,">="&$A10,'寄样履约'!$H$2:$H$301,"<"&$C10),SUMIFS('寄样履约'!$R$2:$R$301,'寄样履约'!$A$2:$A$301,"<>",'寄样履约'!$H$2:$H$301,">="&$A10,'寄样履约'!$H$2:$H$301,"<"&$C10,'寄样履约'!$D$2:$D$301,$B10)))
C11: =IF(A11="","",A11+7) | D11: =IF($A11="","",IF($B11="",COUNTIFS('达人线索与合作'!$A$2:$A$301,"<>",'达人线索与合作'!$U$2:$U$301,">="&$A11,'达人线索与合作'!$U$2:$U$301,"<"&$C11),COUNTIFS('达人线索与合作'!$A$2:$A$301,"<>",'达人线索与合作'!$U$2:$U$301,">="&$A11,'达人线索与合作'!$U$2:$U$301,"<"&$C11,'达人线索与合作'!$F$2:$F$301,$B11))) | E11: =IF($A11="","",IF($B11="",COUNTIFS('达人线索与合作'!$A$2:$A$301,"<>",'达人线索与合作'!$AC$2:$AC$301,">="&$A11,'达人线索与合作'!$AC$2:$AC$301,"<"&$C11),COUNTIFS('达人线索与合作'!$A$2:$A$301,"<>",'达人线索与合作'!$AC$2:$AC$301,">="&$A11,'达人线索与合作'!$AC$2:$AC$301,"<"&$C11,'达人线索与合作'!$F$2:$F$301,$B11))) | F11: =IF($A11="","",IF($B11="",COUNTIFS('达人线索与合作'!$B$2:$B$301,"<>",'达人线索与合作'!$AD$2:$AD$301,">="&$A11,'达人线索与合作'!$AD$2:$AD$301,"<"&$C11),COUNTIFS('达人线索与合作'!$B$2:$B$301,"<>",'达人线索与合作'!$AD$2:$AD$301,">="&$A11,'达人线索与合作'!$AD$2:$AD$301,"<"&$C11,'达人线索与合作'!$F$2:$F$301,$B11))) | G11: =IF($A11="","",IF($B11="",COUNTIFS('寄样履约'!$A$2:$A$301,"<>",'寄样履约'!$H$2:$H$301,">="&$A11,'寄样履约'!$H$2:$H$301,"<"&$C11),COUNTIFS('寄样履约'!$A$2:$A$301,"<>",'寄样履约'!$H$2:$H$301,">="&$A11,'寄样履约'!$H$2:$H$301,"<"&$C11,'寄样履约'!$D$2:$D$301,$B11))) | H11: =IF($A11="","",IF($B11="",COUNTIFS('寄样履约'!$A$2:$A$301,"<>",'寄样履约'!$K$2:$K$301,">="&$A11,'寄样履约'!$K$2:$K$301,"<"&$C11),COUNTIFS('寄样履约'!$A$2:$A$301,"<>",'寄样履约'!$K$2:$K$301,">="&$A11,'寄样履约'!$K$2:$K$301,"<"&$C11,'寄样履约'!$D$2:$D$301,$B11))) | I11: =IF($A11="","",IF($B11="",SUMIFS('视频与订单复盘'!$AG$2:$AG$301,'视频与订单复盘'!$I$2:$I$301,">="&$A11,'视频与订单复盘'!$I$2:$I$301,"<"&$C11),SUMIFS('视频与订单复盘'!$AG$2:$AG$301,'视频与订单复盘'!$I$2:$I$301,">="&$A11,'视频与订单复盘'!$I$2:$I$301,"<"&$C11,'视频与订单复盘'!$H$2:$H$301,$B11))) | J11: =IF($A11="","",IF($B11="",SUMIFS('视频与订单复盘'!$P$2:$P$301,'视频与订单复盘'!$I$2:$I$301,">="&$A11,'视频与订单复盘'!$I$2:$I$301,"<"&$C11,'视频与订单复盘'!$AF$2:$AF$301,"可汇总"),SUMIFS('视频与订单复盘'!$P$2:$P$301,'视频与订单复盘'!$I$2:$I$301,">="&$A11,'视频与订单复盘'!$I$2:$I$301,"<"&$C11,'视频与订单复盘'!$AF$2:$AF$301,"可汇总",'视频与订单复盘'!$H$2:$H$301,$B11))) | K11: =IF($A11="","",IF($B11="",SUMIFS('视频与订单复盘'!$Y$2:$Y$301,'视频与订单复盘'!$I$2:$I$301,">="&$A11,'视频与订单复盘'!$I$2:$I$301,"<"&$C11,'视频与订单复盘'!$AF$2:$AF$301,"可汇总"),SUMIFS('视频与订单复盘'!$Y$2:$Y$301,'视频与订单复盘'!$I$2:$I$301,">="&$A11,'视频与订单复盘'!$I$2:$I$301,"<"&$C11,'视频与订单复盘'!$AF$2:$AF$301,"可汇总",'视频与订单复盘'!$H$2:$H$301,$B11))) | L11: =IF($A11="","",IF($B11="",SUMIFS('寄样履约'!$R$2:$R$301,'寄样履约'!$A$2:$A$301,"<>",'寄样履约'!$H$2:$H$301,">="&$A11,'寄样履约'!$H$2:$H$301,"<"&$C11),SUMIFS('寄样履约'!$R$2:$R$301,'寄样履约'!$A$2:$A$301,"<>",'寄样履约'!$H$2:$H$301,">="&$A11,'寄样履约'!$H$2:$H$301,"<"&$C11,'寄样履约'!$D$2:$D$301,$B11)))
C12: =IF(A12="","",A12+7) | D12: =IF($A12="","",IF($B12="",COUNTIFS('达人线索与合作'!$A$2:$A$301,"<>",'达人线索与合作'!$U$2:$U$301,">="&$A12,'达人线索与合作'!$U$2:$U$301,"<"&$C12),COUNTIFS('达人线索与合作'!$A$2:$A$301,"<>",'达人线索与合作'!$U$2:$U$301,">="&$A12,'达人线索与合作'!$U$2:$U$301,"<"&$C12,'达人线索与合作'!$F$2:$F$301,$B12))) | E12: =IF($A12="","",IF($B12="",COUNTIFS('达人线索与合作'!$A$2:$A$301,"<>",'达人线索与合作'!$AC$2:$AC$301,">="&$A12,'达人线索与合作'!$AC$2:$AC$301,"<"&$C12),COUNTIFS('达人线索与合作'!$A$2:$A$301,"<>",'达人线索与合作'!$AC$2:$AC$301,">="&$A12,'达人线索与合作'!$AC$2:$AC$301,"<"&$C12,'达人线索与合作'!$F$2:$F$301,$B12))) | F12: =IF($A12="","",IF($B12="",COUNTIFS('达人线索与合作'!$B$2:$B$301,"<>",'达人线索与合作'!$AD$2:$AD$301,">="&$A12,'达人线索与合作'!$AD$2:$AD$301,"<"&$C12),COUNTIFS('达人线索与合作'!$B$2:$B$301,"<>",'达人线索与合作'!$AD$2:$AD$301,">="&$A12,'达人线索与合作'!$AD$2:$AD$301,"<"&$C12,'达人线索与合作'!$F$2:$F$301,$B12))) | G12: =IF($A12="","",IF($B12="",COUNTIFS('寄样履约'!$A$2:$A$301,"<>",'寄样履约'!$H$2:$H$301,">="&$A12,'寄样履约'!$H$2:$H$301,"<"&$C12),COUNTIFS('寄样履约'!$A$2:$A$301,"<>",'寄样履约'!$H$2:$H$301,">="&$A12,'寄样履约'!$H$2:$H$301,"<"&$C12,'寄样履约'!$D$2:$D$301,$B12))) | H12: =IF($A12="","",IF($B12="",COUNTIFS('寄样履约'!$A$2:$A$301,"<>",'寄样履约'!$K$2:$K$301,">="&$A12,'寄样履约'!$K$2:$K$301,"<"&$C12),COUNTIFS('寄样履约'!$A$2:$A$301,"<>",'寄样履约'!$K$2:$K$301,">="&$A12,'寄样履约'!$K$2:$K$301,"<"&$C12,'寄样履约'!$D$2:$D$301,$B12))) | I12: =IF($A12="","",IF($B12="",SUMIFS('视频与订单复盘'!$AG$2:$AG$301,'视频与订单复盘'!$I$2:$I$301,">="&$A12,'视频与订单复盘'!$I$2:$I$301,"<"&$C12),SUMIFS('视频与订单复盘'!$AG$2:$AG$301,'视频与订单复盘'!$I$2:$I$301,">="&$A12,'视频与订单复盘'!$I$2:$I$301,"<"&$C12,'视频与订单复盘'!$H$2:$H$301,$B12))) | J12: =IF($A12="","",IF($B12="",SUMIFS('视频与订单复盘'!$P$2:$P$301,'视频与订单复盘'!$I$2:$I$301,">="&$A12,'视频与订单复盘'!$I$2:$I$301,"<"&$C12,'视频与订单复盘'!$AF$2:$AF$301,"可汇总"),SUMIFS('视频与订单复盘'!$P$2:$P$301,'视频与订单复盘'!$I$2:$I$301,">="&$A12,'视频与订单复盘'!$I$2:$I$301,"<"&$C12,'视频与订单复盘'!$AF$2:$AF$301,"可汇总",'视频与订单复盘'!$H$2:$H$301,$B12))) | K12: =IF($A12="","",IF($B12="",SUMIFS('视频与订单复盘'!$Y$2:$Y$301,'视频与订单复盘'!$I$2:$I$301,">="&$A12,'视频与订单复盘'!$I$2:$I$301,"<"&$C12,'视频与订单复盘'!$AF$2:$AF$301,"可汇总"),SUMIFS('视频与订单复盘'!$Y$2:$Y$301,'视频与订单复盘'!$I$2:$I$301,">="&$A12,'视频与订单复盘'!$I$2:$I$301,"<"&$C12,'视频与订单复盘'!$AF$2:$AF$301,"可汇总",'视频与订单复盘'!$H$2:$H$301,$B12))) | L12: =IF($A12="","",IF($B12="",SUMIFS('寄样履约'!$R$2:$R$301,'寄样履约'!$A$2:$A$301,"<>",'寄样履约'!$H$2:$H$301,">="&$A12,'寄样履约'!$H$2:$H$301,"<"&$C12),SUMIFS('寄样履约'!$R$2:$R$301,'寄样履约'!$A$2:$A$301,"<>",'寄样履约'!$H$2:$H$301,">="&$A12,'寄样履约'!$H$2:$H$301,"<"&$C12,'寄样履约'!$D$2:$D$301,$B12)))
C13: =IF(A13="","",A13+7) | D13: =IF($A13="","",IF($B13="",COUNTIFS('达人线索与合作'!$A$2:$A$301,"<>",'达人线索与合作'!$U$2:$U$301,">="&$A13,'达人线索与合作'!$U$2:$U$301,"<"&$C13),COUNTIFS('达人线索与合作'!$A$2:$A$301,"<>",'达人线索与合作'!$U$2:$U$301,">="&$A13,'达人线索与合作'!$U$2:$U$301,"<"&$C13,'达人线索与合作'!$F$2:$F$301,$B13))) | E13: =IF($A13="","",IF($B13="",COUNTIFS('达人线索与合作'!$A$2:$A$301,"<>",'达人线索与合作'!$AC$2:$AC$301,">="&$A13,'达人线索与合作'!$AC$2:$AC$301,"<"&$C13),COUNTIFS('达人线索与合作'!$A$2:$A$301,"<>",'达人线索与合作'!$AC$2:$AC$301,">="&$A13,'达人线索与合作'!$AC$2:$AC$301,"<"&$C13,'达人线索与合作'!$F$2:$F$301,$B13))) | F13: =IF($A13="","",IF($B13="",COUNTIFS('达人线索与合作'!$B$2:$B$301,"<>",'达人线索与合作'!$AD$2:$AD$301,">="&$A13,'达人线索与合作'!$AD$2:$AD$301,"<"&$C13),COUNTIFS('达人线索与合作'!$B$2:$B$301,"<>",'达人线索与合作'!$AD$2:$AD$301,">="&$A13,'达人线索与合作'!$AD$2:$AD$301,"<"&$C13,'达人线索与合作'!$F$2:$F$301,$B13))) | G13: =IF($A13="","",IF($B13="",COUNTIFS('寄样履约'!$A$2:$A$301,"<>",'寄样履约'!$H$2:$H$301,">="&$A13,'寄样履约'!$H$2:$H$301,"<"&$C13),COUNTIFS('寄样履约'!$A$2:$A$301,"<>",'寄样履约'!$H$2:$H$301,">="&$A13,'寄样履约'!$H$2:$H$301,"<"&$C13,'寄样履约'!$D$2:$D$301,$B13))) | H13: =IF($A13="","",IF($B13="",COUNTIFS('寄样履约'!$A$2:$A$301,"<>",'寄样履约'!$K$2:$K$301,">="&$A13,'寄样履约'!$K$2:$K$301,"<"&$C13),COUNTIFS('寄样履约'!$A$2:$A$301,"<>",'寄样履约'!$K$2:$K$301,">="&$A13,'寄样履约'!$K$2:$K$301,"<"&$C13,'寄样履约'!$D$2:$D$301,$B13))) | I13: =IF($A13="","",IF($B13="",SUMIFS('视频与订单复盘'!$AG$2:$AG$301,'视频与订单复盘'!$I$2:$I$301,">="&$A13,'视频与订单复盘'!$I$2:$I$301,"<"&$C13),SUMIFS('视频与订单复盘'!$AG$2:$AG$301,'视频与订单复盘'!$I$2:$I$301,">="&$A13,'视频与订单复盘'!$I$2:$I$301,"<"&$C13,'视频与订单复盘'!$H$2:$H$301,$B13))) | J13: =IF($A13="","",IF($B13="",SUMIFS('视频与订单复盘'!$P$2:$P$301,'视频与订单复盘'!$I$2:$I$301,">="&$A13,'视频与订单复盘'!$I$2:$I$301,"<"&$C13,'视频与订单复盘'!$AF$2:$AF$301,"可汇总"),SUMIFS('视频与订单复盘'!$P$2:$P$301,'视频与订单复盘'!$I$2:$I$301,">="&$A13,'视频与订单复盘'!$I$2:$I$301,"<"&$C13,'视频与订单复盘'!$AF$2:$AF$301,"可汇总",'视频与订单复盘'!$H$2:$H$301,$B13))) | K13: =IF($A13="","",IF($B13="",SUMIFS('视频与订单复盘'!$Y$2:$Y$301,'视频与订单复盘'!$I$2:$I$301,">="&$A13,'视频与订单复盘'!$I$2:$I$301,"<"&$C13,'视频与订单复盘'!$AF$2:$AF$301,"可汇总"),SUMIFS('视频与订单复盘'!$Y$2:$Y$301,'视频与订单复盘'!$I$2:$I$301,">="&$A13,'视频与订单复盘'!$I$2:$I$301,"<"&$C13,'视频与订单复盘'!$AF$2:$AF$301,"可汇总",'视频与订单复盘'!$H$2:$H$301,$B13))) | L13: =IF($A13="","",IF($B13="",SUMIFS('寄样履约'!$R$2:$R$301,'寄样履约'!$A$2:$A$301,"<>",'寄样履约'!$H$2:$H$301,">="&$A13,'寄样履约'!$H$2:$H$301,"<"&$C13),SUMIFS('寄样履约'!$R$2:$R$301,'寄样履约'!$A$2:$A$301,"<>",'寄样履约'!$H$2:$H$301,">="&$A13,'寄样履约'!$H$2:$H$301,"<"&$C13,'寄样履约'!$D$2:$D$301,$B13)))
